Workbook
Name SegmentaciónDeDatos_Activo: #N/A

Sheet Operaciones
A1: Capital inicial | B1: 72.04 | C1: =B1+SUM(AH:AH) -> #REF!
A2: Fecha Entrada | B2: Hora Entrada | C2: Activo | F2: Fractales | J2: S/R | K2: Observaciones | L2: Fractales | M2: P_Stock | N2: P_BL | O2: P_R | P2: P_T | Q2: P_global | R2: ENTRADA | S2: Precio Entrada | T2: SL (%) | U2: TP (%) | V2: TIEMPO | W2: SL Precio | X2: TP Precio | Y2: Precio Actual | Z2: Trailing stop | AA2: Precio cierre | AB2: Tamaño ($) | AC2: Resultado | AD2: Fecha Cierre | AE2: Hora Cierre | AF2: Motivo Cierre | AG2: % Retorno | AH2: $ Retorno | AI2: Indicacion | AJ2: Observaciones | AK2: DIAS
A3: 45917 | B3: 0.64771991 | C3: AUDCAD | D3: =IF(COUNTIF(#REF!,"<>NAN")=0, 0, IF(AND(OR(#REF!=#REF!,#REF!="NAN"), OR(#REF!=#REF!,#REF!="NAN"), OR(#REF!=#REF!,#REF!="NAN")),#REF!, 0)) -> #REF! | E3: =IF(#REF!="NAN","",IF( AND(OR(#REF!=#REF!,#REF!="NAN"), OR(#REF!=#REF!,#REF!="NAN"), OR(#REF!=#REF!,#REF!="NAN")), 1, 0)) -> #REF! | G3: =IF(OR(#REF!="UP",#REF!="DOWN"),1,0) -> #REF! | H3: =IF(OR(#REF!="UP",#REF!="DOWN"),1,0) -> #REF! | I3: =IF(OR(#REF!="UP",#REF!="DOWN"),1,0) -> #REF! | M3: =IF(OR(#REF!="UP",#REF!="DOWN"),1,1) -> #REF! | N3: =IF(OR(#REF!="UP",#REF!="DOWN"),VLOOKUP($C3,Configuración!$H$2:$K$11,3),1) -> #REF! | O3: =IF(OR(#REF!="UP",#REF!="DOWN"),VLOOKUP($C3,Configuración!$H$2:$K$11,4),1) -> #REF! | P3: =IF(SUM(G3:I3)=0, 0, IF(SUM(G3:I3)=1, G3*M3 + H3*N3 + I3*O3, IF(SUM(G3:I3)=2, 1 - PRODUCT( IF(G3=1,1-M3,1), IF(H3=1,1-N3,1), IF(I3=1,1-O3,1) ), IF(SUM(G3:I3)=3, 1 - PRODUCT(1-M3,1-N3,1-O3), 0 ) ) ) ) -> #REF! | Q3: =P3*E3 -> #REF! | R3: =IF(AND(OR(D3="UP",D3="DOWN"), Q3>0.95), D3, 0) -> #REF! | T3: =IF(R3<>0,Configuración!$E$2,0) -> #REF! | U3: =IF(R3<>0,Configuración!$F$2,0) -> #REF! | V3: =IF(R3<>0,Configuración!$G$2,0) -> #REF! | W3: =IF(R3="DOWN",S3+(S3*T3/100),S3-(S3*T3/100)) -> #REF! | X3: =IF(R3="DOWN",S3-(S3*U3/100),S3+(S3*U3/100)) -> #REF! | Z3: =IF(R3="DOWN",IF(Y3 < S3 * (1 - 0.01), Y3 * (1 + 0.005), ""),IF(Y3 > S3 * (1 + 0.01), Y3 * (1 - 0.005), "")) -> #REF! | AB3: =(($B$1) *(T3))/100 -> #REF! | AG3: =IF(R3="DOWN",(S3-AA3)/S3*1000,(AA3-S3)/S3*1000) -> #REF! | AH3: =AB3*(AG3) -> #REF! | AI3: =IF(AK3<V3,"MANTENER","CERRAR") -> #REF!
A4: 45917 | B4: 0.65180556 | C4: AUDUSD | D4: =IF(COUNTIF(#REF!,"<>NAN")=0, 0, IF(AND(OR(#REF!=#REF!,#REF!="NAN"), OR(#REF!=#REF!,#REF!="NAN"), OR(#REF!=#REF!,#REF!="NAN")),#REF!, 0)) -> #REF! | E4: =IF(#REF!="NAN","",IF( AND(OR(#REF!=#REF!,#REF!="NAN"), OR(#REF!=#REF!,#REF!="NAN"), OR(#REF!=#REF!,#REF!="NAN")), 1, 0)) -> #REF! | G4: =IF(OR(#REF!="UP",#REF!="DOWN"),1,0) -> #REF! | H4: =IF(OR(#REF!="UP",#REF!="DOWN"),1,0) -> #REF! | I4: =IF(OR(#REF!="UP",#REF!="DOWN"),1,0) -> #REF! | M4: =IF(OR(#REF!="UP",#REF!="DOWN"),1,1) -> #REF! | N4: =IF(OR(#REF!="UP",#REF!="DOWN"),VLOOKUP($C4,Configuración!$H$2:$K$11,3),1) -> #REF! | O4: =IF(OR(#REF!="UP",#REF!="DOWN"),VLOOKUP($C4,Configuración!$H$2:$K$11,4),1) -> #REF! | P4: =IF(SUM(G4:I4)=0, 0, IF(SUM(G4:I4)=1, G4*M4 + H4*N4 + I4*O4, IF(SUM(G4:I4)=2, 1 - PRODUCT( IF(G4=1,1-M4,1), IF(H4=1,1-N4,1), IF(I4=1,1-O4,1) ), IF(SUM(G4:I4)=3, 1 - PRODUCT(1-M4,1-N4,1-O4), 0 ) ) ) ) -> #REF! | Q4: =P4*E4 -> #REF! | R4: =IF(AND(OR(D4="UP",D4="DOWN"), Q4>0.95), D4, 0) -> #REF! | T4: =IF(R4<>0,Configuración!$E$2,0) -> #REF! | U4: =IF(R4<>0,Configuración!$F$2,0) -> #REF! | V4: =IF(R4<>0,Configuración!$G$2,0) -> #REF! | W4: =IF(R4="DOWN",S4+(S4*T4/100),S4-(S4*T4/100)) -> #REF! | X4: =IF(R4="DOWN",S4-(S4*U4/100),S4+(S4*U4/100)) -> #REF! | Z4: =IF(R4="DOWN",IF(Y4 < S4 * (1 - 0.01), Y4 * (1 + 0.005), ""),IF(Y4 > S4 * (1 + 0.01), Y4 * (1 - 0.005), "")) -> #REF! | AB4: =(($B$1) *(T4))/100 -> #REF! | AC4: =IF(AH4>0,"WIN",IF(AH4<0,"LOSS","BREAKEVEN")) -> #REF! | AG4: =IF(R4="DOWN",(S4-AA4)/S4*1000,(AA4-S4)/S4*1000) -> #REF! | AH4: =AB4*(AG4) -> #REF! | AI4: =IF(AK4<V4,"MANTENER","CERRAR") -> #REF!
A5: 45917 | B5: 0.63921296 | C5: CADCHF | D5: =IF(COUNTIF(#REF!,"<>NAN")=0, 0, IF(AND(OR(#REF!=#REF!,#REF!="NAN"), OR(#REF!=#REF!,#REF!="NAN"), OR(#REF!=#REF!,#REF!="NAN")),#REF!, 0)) -> #REF! | E5: =IF(#REF!="NAN","",IF( AND(OR(#REF!=#REF!,#REF!="NAN"), OR(#REF!=#REF!,#REF!="NAN"), OR(#REF!=#REF!,#REF!="NAN")), 1, 0)) -> #REF! | G5: =IF(OR(#REF!="UP",#REF!="DOWN"),1,0) -> #REF! | H5: =IF(OR(#REF!="UP",#REF!="DOWN"),1,0) -> #REF! | I5: =IF(OR(#REF!="UP",#REF!="DOWN"),1,0) -> #REF! | M5: =IF(OR(#REF!="UP",#REF!="DOWN"),1,1) -> #REF! | N5: =IF(OR(#REF!="UP",#REF!="DOWN"),VLOOKUP($C5,Configuración!$H$2:$K$11,3),1) -> #REF! | O5: =IF(OR(#REF!="UP",#REF!="DOWN"),VLOOKUP($C5,Configuración!$H$2:$K$11,4),1) -> #REF! | P5: =IF(SUM(G5:I5)=0, 0, IF(SUM(G5:I5)=1, G5*M5 + H5*N5 + I5*O5, IF(SUM(G5:I5)=2, 1 - PRODUCT( IF(G5=1,1-M5,1), IF(H5=1,1-N5,1), IF(I5=1,1-O5,1) ), IF(SUM(G5:I5)=3, 1 - PRODUCT(1-M5,1-N5,1-O5), 0 ) ) ) ) -> #REF! | Q5: =P5*E5 -> #REF! | R5: =IF(AND(OR(D5="UP",D5="DOWN"), Q5>0.95), D5, 0) -> #REF! | T5: =IF(R5<>0,Configuración!$E$2,0) -> #REF! | U5: =IF(R5<>0,Configuración!$F$2,0) -> #REF! | V5: =IF(R5<>0,Configuración!$G$2,0) -> #REF! | W5: =IF(R5="DOWN",S5+(S5*T5/100),S5-(S5*T5/100)) -> #REF! | X5: =IF(R5="DOWN",S5-(S5*U5/100),S5+(S5*U5/100)) -> #REF! | Z5: =IF(R5="DOWN",IF(Y5 < S5 * (1 - 0.01), Y5 * (1 + 0.005), ""),IF(Y5 > S5 * (1 + 0.01), Y5 * (1 - 0.005), "")) -> #REF! | AB5: =(($B$1) *(T5))/100 -> #REF! | AC5: =IF(AH5>0,"WIN",IF(AH5<0,"LOSS","BREAKEVEN")) -> #REF! | AG5: =IF(R5="DOWN",(S5-AA5)/S5*1000,(AA5-S5)/S5*1000) -> #REF! | AH5: =AB5*(AG5) -> #REF! | AI5: =IF(AK5<V5,"MANTENER","CERRAR") -> #REF!
A6: 45917 | B6: 0.62662037 | C6: CHFJPY | D6: =IF(COUNTIF(#REF!,"<>NAN")=0, 0, IF(AND(OR(#REF!=#REF!,#REF!="NAN"), OR(#REF!=#REF!,#REF!="NAN"), OR(#REF!=#REF!,#REF!="NAN")),#REF!, 0)) -> #REF! | E6: =IF(#REF!="NAN","",IF( AND(OR(#REF!=#REF!,#REF!="NAN"), OR(#REF!=#REF!,#REF!="NAN"), OR(#REF!=#REF!,#REF!="NAN")), 1, 0)) -> #REF! | G6: =IF(OR(#REF!="UP",#REF!="DOWN"),1,0) -> #REF! | H6: =IF(OR(#REF!="UP",#REF!="DOWN"),1,0) -> #REF! | I6: =IF(OR(#REF!="UP",#REF!="DOWN"),1,0) -> #REF! | M6: =IF(OR(#REF!="UP",#REF!="DOWN"),1,1) -> #REF! | N6: =IF(OR(#REF!="UP",#REF!="DOWN"),VLOOKUP($C6,Configuración!$H$2:$K$11,3),1) -> #REF! | O6: =IF(OR(#REF!="UP",#REF!="DOWN"),VLOOKUP($C6,Configuración!$H$2:$K$11,4),1) -> #REF! | P6: =IF(SUM(G6:I6)=0, 0, IF(SUM(G6:I6)=1, G6*M6 + H6*N6 + I6*O6, IF(SUM(G6:I6)=2, 1 - PRODUCT( IF(G6=1,1-M6,1), IF(H6=1,1-N6,1), IF(I6=1,1-O6,1) ), IF(SUM(G6:I6)=3, 1 - PRODUCT(1-M6,1-N6,1-O6), 0 ) ) ) ) -> #REF! | Q6: =P6*E6 -> #REF! | R6: =IF(AND(OR(D6="UP",D6="DOWN"), Q6>0.95), D6, 0) -> #REF! | T6: =IF(R6<>0,Configuración!$E$2,0) -> #REF! | U6: =IF(R6<>0,Configuración!$F$2,0) -> #REF! | V6: =IF(R6<>0,Configuración!$G$2,0) -> #REF! | W6: =IF(R6="DOWN",S6+(S6*T6/100),S6-(S6*T6/100)) -> #REF! | X6: =IF(R6="DOWN",S6-(S6*U6/100),S6+(S6*U6/100)) -> #REF! | Z6: =IF(R6="DOWN",IF(Y6 < S6 * (1 - 0.01), Y6 * (1 + 0.005), ""),IF(Y6 > S6 * (1 + 0.01), Y6 * (1 - 0.005), "")) -> #REF! | AB6: =(($B$1) *(T6))/100 -> #REF! | AG6: =IF(R6="DOWN",(S6-AA6)/S6*1000,(AA6-S6)/S6*1000) -> #REF! | AH6: =AB6*(AG6) -> #REF! | AI6: =IF(AK6<V6,"MANTENER","CERRAR") -> #REF!
A7: 45917 | B7: 0.61402778 | C7: EURAUD | D7: =IF(COUNTIF(#REF!,"<>NAN")=0, 0, IF(AND(OR(#REF!=#REF!,#REF!="NAN"), OR(#REF!=#REF!,#REF!="NAN"), OR(#REF!=#REF!,#REF!="NAN")),#REF!, 0)) -> #REF! | E7: =IF(#REF!="NAN","",IF( AND(OR(#REF!=#REF!,#REF!="NAN"), OR(#REF!=#REF!,#REF!="NAN"), OR(#REF!=#REF!,#REF!="NAN")), 1, 0)) -> #REF! | G7: =IF(OR(#REF!="UP",#REF!="DOWN"),1,0) -> #REF! | H7: =IF(OR(#REF!="UP",#REF!="DOWN"),1,0) -> #REF! | I7: =IF(OR(#REF!="UP",#REF!="DOWN"),1,0) -> #REF! | M7: =IF(OR(#REF!="UP",#REF!="DOWN"),1,1) -> #REF! | N7: =IF(OR(#REF!="UP",#REF!="DOWN"),VLOOKUP($C7,Configuración!$H$2:$K$11,3),1) -> #REF! | O7: =IF(OR(#REF!="UP",#REF!="DOWN"),VLOOKUP($C7,Configuración!$H$2:$K$11,4),1) -> #REF! | P7: =IF(SUM(G7:I7)=0, 0, IF(SUM(G7:I7)=1, G7*M7 + H7*N7 + I7*O7, IF(SUM(G7:I7)=2, 1 - PRODUCT( IF(G7=1,1-M7,1), IF(H7=1,1-N7,1), IF(I7=1,1-O7,1) ), IF(SUM(G7:I7)=3, 1 - PRODUCT(1-M7,1-N7,1-O7), 0 ) ) ) ) -> #REF! | Q7: =P7*E7 -> #REF! | R7: =IF(AND(OR(D7="UP",D7="DOWN"), Q7>0.95), D7, 0) -> #REF! | T7: =IF(R7<>0,Configuración!$E$2,0) -> #REF! | U7: =IF(R7<>0,Configuración!$F$2,0) -> #REF! | V7: =IF(R7<>0,Configuración!$G$2,0) -> #REF! | W7: =IF(R7="DOWN",S7+(S7*T7/100),S7-(S7*T7/100)) -> #REF! | X7: =IF(R7="DOWN",S7-(S7*U7/100),S7+(S7*U7/100)) -> #REF! | Z7: =IF(R7="DOWN",IF(Y7 < S7 * (1 - 0.01), Y7 * (1 + 0.005), ""),IF(Y7 > S7 * (1 + 0.01), Y7 * (1 - 0.005), "")) -> #REF! | AB7: =(($B$1) *(T7))/100 -> #REF! | AG7: =IF(R7="DOWN",(S7-AA7)/S7*1000,(AA7-S7)/S7*1000) -> #REF! | AH7: =AB7*(AG7) -> #REF! | AI7: =IF(AK7<V7,"MANTENER","CERRAR") -> #REF!
A8: 45917 | B8: 0.60143519 | C8: EURUSD | D8: =IF(COUNTIF(#REF!,"<>NAN")=0, 0, IF(AND(OR(#REF!=#REF!,#REF!="NAN"), OR(#REF!=#REF!,#REF!="NAN"), OR(#REF!=#REF!,#REF!="NAN")),#REF!, 0)) -> #REF! | E8: =IF(#REF!="NAN","",IF( AND(OR(#REF!=#REF!,#REF!="NAN"), OR(#REF!=#REF!,#REF!="NAN"), OR(#REF!=#REF!,#REF!="NAN")), 1, 0)) -> #REF! | G8: =IF(OR(#REF!="UP",#REF!="DOWN"),1,0) -> #REF! | H8: =IF(OR(#REF!="UP",#REF!="DOWN"),1,0) -> #REF! | I8: =IF(OR(#REF!="UP",#REF!="DOWN"),1,0) -> #REF! | M8: =IF(OR(#REF!="UP",#REF!="DOWN"),1,1) -> #REF! | N8: =IF(OR(#REF!="UP",#REF!="DOWN"),VLOOKUP($C8,Configuración!$H$2:$K$11,3),1) -> #REF! | O8: =IF(OR(#REF!="UP",#REF!="DOWN"),VLOOKUP($C8,Configuración!$H$2:$K$11,4),1) -> #REF! | P8: =IF(SUM(G8:I8)=0, 0, IF(SUM(G8:I8)=1, G8*M8 + H8*N8 + I8*O8, IF(SUM(G8:I8)=2, 1 - PRODUCT( IF(G8=1,1-M8,1), IF(H8=1,1-N8,1), IF(I8=1,1-O8,1) ), IF(SUM(G8:I8)=3, 1 - PRODUCT(1-M8,1-N8,1-O8), 0 ) ) ) ) -> #REF! | Q8: =P8*E8 -> #REF! | R8: =IF(AND(OR(D8="UP",D8="DOWN"), Q8>0.95), D8, 0) -> #REF! | T8: =IF(R8<>0,Configuración!$E$2,0) -> #REF! | U8: =IF(R8<>0,Configuración!$F$2,0) -> #REF! | V8: =IF(R8<>0,Configuración!$G$2,0) -> #REF! | W8: =IF(R8="DOWN",S8+(S8*T8/100),S8-(S8*T8/100)) -> #REF! | X8: =IF(R8="DOWN",S8-(S8*U8/100),S8+(S8*U8/100)) -> #REF! | Z8: =IF(R8="DOWN",IF(Y8 < S8 * (1 - 0.01), Y8 * (1 + 0.005), ""),IF(Y8 > S8 * (1 + 0.01), Y8 * (1 - 0.005), "")) -> #REF! | AB8: =(($B$1) *(T8))/100 -> #REF! | AG8: =IF(R8="DOWN",(S8-AA8)/S8*1000,(AA8-S8)/S8*1000) -> #REF! | AH8: =AB8*(AG8) -> #REF! | AI8: =IF(AK8<V8,"MANTENER","CERRAR") -> #REF!
A9: 45917 | B9: 0.58884259 | C9: GBPUSD | D9: =IF(COUNTIF(#REF!,"<>NAN")=0, 0, IF(AND(OR(#REF!=#REF!,#REF!="NAN"), OR(#REF!=#REF!,#REF!="NAN"), OR(#REF!=#REF!,#REF!="NAN")),#REF!, 0)) -> #REF! | E9: =IF(#REF!="NAN","",IF( AND(OR(#REF!=#REF!,#REF!="NAN"), OR(#REF!=#REF!,#REF!="NAN"), OR(#REF!=#REF!,#REF!="NAN")), 1, 0)) -> #REF! | G9: =IF(OR(#REF!="UP",#REF!="DOWN"),1,0) -> #REF! | H9: =IF(OR(#REF!="UP",#REF!="DOWN"),1,0) -> #REF! | I9: =IF(OR(#REF!="UP",#REF!="DOWN"),1,0) -> #REF! | M9: =IF(OR(#REF!="UP",#REF!="DOWN"),1,1) -> #REF! | N9: =IF(OR(#REF!="UP",#REF!="DOWN"),VLOOKUP($C9,Configuración!$H$2:$K$11,3),1) -> #REF! | O9: =IF(OR(#REF!="UP",#REF!="DOWN"),VLOOKUP($C9,Configuración!$H$2:$K$11,4),1) -> #REF! | P9: =IF(SUM(G9:I9)=0, 0, IF(SUM(G9:I9)=1, G9*M9 + H9*N9 + I9*O9, IF(SUM(G9:I9)=2, 1 - PRODUCT( IF(G9=1,1-M9,1), IF(H9=1,1-N9,1), IF(I9=1,1-O9,1) ), IF(SUM(G9:I9)=3, 1 - PRODUCT(1-M9,1-N9,1-O9), 0 ) ) ) ) -> #REF! | Q9: =P9*E9 -> #REF! | R9: =IF(AND(OR(D9="UP",D9="DOWN"), Q9>0.95), D9, 0) -> #REF! | T9: =IF(R9<>0,Configuración!$E$2,0) -> #REF! | U9: =IF(R9<>0,Configuración!$F$2,0) -> #REF! | V9: =IF(R9<>0,Configuración!$G$2,0) -> #REF! | W9: =IF(R9="DOWN",S9+(S9*T9/100),S9-(S9*T9/100)) -> #REF! | X9: =IF(R9="DOWN",S9-(S9*U9/100),S9+(S9*U9/100)) -> #REF! | Z9: =IF(R9="DOWN",IF(Y9 < S9 * (1 - 0.01), Y9 * (1 + 0.005), ""),IF(Y9 > S9 * (1 + 0.01), Y9 * (1 - 0.005), "")) -> #REF! | AB9: =(($B$1) *(T9))/100 -> #REF! | AG9: =IF(R9="DOWN",(S9-AA9)/S9*1000,(AA9-S9)/S9*1000) -> #REF! | AH9: =AB9*(AG9) -> #REF! | AI9: =IF(AK9<V9,"MANTENER","CERRAR") -> #REF!
A10: 45917 | B10: 0.57625 | C10: USDCAD | D10: =IF(COUNTIF(#REF!,"<>NAN")=0, 0, IF(AND(OR(#REF!=#REF!,#REF!="NAN"), OR(#REF!=#REF!,#REF!="NAN"), OR(#REF!=#REF!,#REF!="NAN")),#REF!, 0)) -> #REF! | E10: =IF(#REF!="NAN","",IF( AND(OR(#REF!=#REF!,#REF!="NAN"), OR(#REF!=#REF!,#REF!="NAN"), OR(#REF!=#REF!,#REF!="NAN")), 1, 0)) -> #REF! | G10: =IF(OR(#REF!="UP",#REF!="DOWN"),1,0) -> #REF! | H10: =IF(OR(#REF!="UP",#REF!="DOWN"),1,0) -> #REF! | I10: =IF(OR(#REF!="UP",#REF!="DOWN"),1,0) -> #REF! | M10: =IF(OR(#REF!="UP",#REF!="DOWN"),1,1) -> #REF! | N10: =IF(OR(#REF!="UP",#REF!="DOWN"),VLOOKUP($C10,Configuración!$H$2:$K$11,3),1) -> #REF! | O10: =IF(OR(#REF!="UP",#REF!="DOWN"),VLOOKUP($C10,Configuración!$H$2:$K$11,4),1) -> #REF! | P10: =IF(SUM(G10:I10)=0, 0, IF(SUM(G10:I10)=1, G10*M10 + H10*N10 + I10*O10, IF(SUM(G10:I10)=2, 1 - PRODUCT( IF(G10=1,1-M10,1), IF(H10=1,1-N10,1), IF(I10=1,1-O10,1) ), IF(SUM(G10:I10)=3, 1 - PRODUCT(1-M10,1-N10,1-O10), 0 ) ) ) ) -> #REF! | Q10: =P10*E10 -> #REF! | R10: =IF(AND(OR(D10="UP",D10="DOWN"), Q10>0.95), D10, 0) -> #REF! | T10: =IF(R10<>0,Configuración!$E$2,0) -> #REF! | U10: =IF(R10<>0,Configuración!$F$2,0) -> #REF! | V10: =IF(R10<>0,Configuración!$G$2,0) -> #REF! | W10: =IF(R10="DOWN",S10+(S10*T10/100),S10-(S10*T10/100)) -> #REF! | X10: =IF(R10="DOWN",S10-(S10*U10/100),S10+(S10*U10/100)) -> #REF! | Z10: =IF(R10="DOWN",IF(Y10 < S10 * (1 - 0.01), Y10 * (1 + 0.005), ""),IF(Y10 > S10 * (1 + 0.01), Y10 * (1 - 0.005), "")) -> #REF! | AB10: =(($B$1) *(T10))/100 -> #REF! | AG10: =IF(R10="DOWN",(S10-AA10)/S10*1000,(AA10-S10)/S10*1000) -> #REF! | AH10: =AB10*(AG10) -> #REF! | AI10: =IF(AK10<V10,"MANTENER","CERRAR") -> #REF!
A11: 45917 | B11: 0.56365741 | C11: USDCHF | D11: =IF(COUNTIF(#REF!,"<>NAN")=0, 0, IF(AND(OR(#REF!=#REF!,#REF!="NAN"), OR(#REF!=#REF!,#REF!="NAN"), OR(#REF!=#REF!,#REF!="NAN")),#REF!, 0)) -> #REF! | E11: =IF(#REF!="NAN","",IF( AND(OR(#REF!=#REF!,#REF!="NAN"), OR(#REF!=#REF!,#REF!="NAN"), OR(#REF!=#REF!,#REF!="NAN")), 1, 0)) -> #REF! | G11: =IF(OR(#REF!="UP",#REF!="DOWN"),1,0) -> #REF! | H11: =IF(OR(#REF!="UP",#REF!="DOWN"),1,0) -> #REF! | I11: =IF(OR(#REF!="UP",#REF!="DOWN"),1,0) -> #REF! | M11: =IF(OR(#REF!="UP",#REF!="DOWN"),1,1) -> #REF! | N11: =IF(OR(#REF!="UP",#REF!="DOWN"),VLOOKUP($C11,Configuración!$H$2:$K$11,3),1) -> #REF! | O11: =IF(OR(#REF!="UP",#REF!="DOWN"),VLOOKUP($C11,Configuración!$H$2:$K$11,4),1) -> #REF! | P11: =IF(SUM(G11:I11)=0, 0, IF(SUM(G11:I11)=1, G11*M11 + H11*N11 + I11*O11, IF(SUM(G11:I11)=2, 1 - PRODUCT( IF(G11=1,1-M11,1), IF(H11=1,1-N11,1), IF(I11=1,1-O11,1) ), IF(SUM(G11:I11)=3, 1 - PRODUCT(1-M11,1-N11,1-O11), 0 ) ) ) ) -> #REF! | Q11: =P11*E11 -> #REF! | R11: =IF(AND(OR(D11="UP",D11="DOWN"), Q11>0.95), D11, 0) -> #REF! | T11: =IF(R11<>0,Configuración!$E$2,0) -> #REF! | U11: =IF(R11<>0,Configuración!$F$2,0) -> #REF! | V11: =IF(R11<>0,Configuración!$G$2,0) -> #REF! | W11: =IF(R11="DOWN",S11+(S11*T11/100),S11-(S11*T11/100)) -> #REF! | X11: =IF(R11="DOWN",S11-(S11*U11/100),S11+(S11*U11/100)) -> #REF! | Z11: =IF(R11="DOWN",IF(Y11 < S11 * (1 - 0.01), Y11 * (1 + 0.005), ""),IF(Y11 > S11 * (1 + 0.01), Y11 * (1 - 0.005), "")) -> #REF! | AB11: =(($B$1) *(T11))/100 -> #REF! | AC11: =IF(AH11>0,"WIN",IF(AH11<0,"LOSS","BREAKEVEN")) -> #REF! | AG11: =IF(R11="DOWN",(S11-AA11)/S11*1000,(AA11-S11)/S11*1000) -> #REF! | AH11: =AB11*(AG11) -> #REF! | AI11: =IF(AK11<V11,"MANTENER","CERRAR") -> #REF!
A12: 45917 | B12: 0.55106481 | C12: USDJPY | D12: =IF(COUNTIF(#REF!,"<>NAN")=0, 0, IF(AND(OR(#REF!=#REF!,#REF!="NAN"), OR(#REF!=#REF!,#REF!="NAN"), OR(#REF!=#REF!,#REF!="NAN")),#REF!, 0)) -> #REF! | E12: =IF(#REF!="NAN","",IF( AND(OR(#REF!=#REF!,#REF!="NAN"), OR(#REF!=#REF!,#REF!="NAN"), OR(#REF!=#REF!,#REF!="NAN")), 1, 0)) -> #REF! | G12: =IF(OR(#REF!="UP",#REF!="DOWN"),1,0) -> #REF! | H12: =IF(OR(#REF!="UP",#REF!="DOWN"),1,0) -> #REF! | I12: =IF(OR(#REF!="UP",#REF!="DOWN"),1,0) -> #REF! | M12: =IF(OR(#REF!="UP",#REF!="DOWN"),1,1) -> #REF! | N12: =IF(OR(#REF!="UP",#REF!="DOWN"),VLOOKUP($C12,Configuración!$H$2:$K$11,3),1) -> #REF! | O12: =IF(OR(#REF!="UP",#REF!="DOWN"),VLOOKUP($C12,Configuración!$H$2:$K$11,4),1) -> #REF! | P12: =IF(SUM(G12:I12)=0, 0, IF(SUM(G12:I12)=1, G12*M12 + H12*N12 + I12*O12, IF(SUM(G12:I12)=2, 1 - PRODUCT( IF(G12=1,1-M12,1), IF(H12=1,1-N12,1), IF(I12=1,1-O12,1) ), IF(SUM(G12:I12)=3, 1 - PRODUCT(1-M12,1-N12,1-O12), 0 ) ) ) ) -> #REF! | Q12: =P12*E12 -> #REF! | R12: =IF(AND(OR(D12="UP",D12="DOWN"), Q12>0.95), D12, 0) -> #REF! | T12: =IF(R12<>0,Configuración!$E$2,0) -> #REF! | U12: =IF(R12<>0,Configuración!$F$2,0) -> #REF! | V12: =IF(R12<>0,Configuración!$G$2,0) -> #REF! | W12: =IF(R12="DOWN",S12+(S12*T12/100),S12-(S12*T12/100)) -> #REF! | X12: =IF(R12="DOWN",S12-(S12*U12/100),S12+(S12*U12/100)) -> #REF! | Z12: =IF(R12="DOWN",IF(Y12 < S12 * (1 - 0.01), Y12 * (1 + 0.005), ""),IF(Y12 > S12 * (1 + 0.01), Y12 * (1 - 0.005), "")) -> #REF! | AB12: =(($B$1) *(T12))/100 -> #REF! | AG12: =IF(R12="DOWN",(S12-AA12)/S12*1000,(AA12-S12)/S12*1000) -> #REF! | AH12: =AB12*(AG12) -> #REF! | AI12: =IF(AK12<V12,"MANTENER","CERRAR") -> #REF!
A13: 45918 | B13: 0.625 | C13: AUDCAD | D13: =IF(COUNTIF(#REF!,"<>NAN")=0, 0, IF(AND(OR(#REF!=#REF!,#REF!="NAN"), OR(#REF!=#REF!,#REF!="NAN"), OR(#REF!=#REF!,#REF!="NAN")),#REF!, 0)) -> #REF! | E13: =IF(#REF!="NAN","",IF( AND(OR(#REF!=#REF!,#REF!="NAN"), OR(#REF!=#REF!,#REF!="NAN"), OR(#REF!=#REF!,#REF!="NAN")), 1, 0)) -> #REF! | G13: =IF(OR(#REF!="UP",#REF!="DOWN"),1,0) -> #REF! | H13: =IF(OR(#REF!="UP",#REF!="DOWN"),1,0) -> #REF! | I13: =IF(OR(#REF!="UP",#REF!="DOWN"),1,0) -> #REF! | M13: =IF(OR(#REF!="UP",#REF!="DOWN"),1,1) -> #REF! | N13: =IF(OR(#REF!="UP",#REF!="DOWN"),VLOOKUP($C13,Configuración!$H$2:$K$11,3),1) -> #REF! | O13: =IF(OR(#REF!="UP",#REF!="DOWN"),VLOOKUP($C13,Configuración!$H$2:$K$11,4),1) -> #REF! | P13: =IF(SUM(G13:I13)=0, 0, IF(SUM(G13:I13)=1, G13*M13 + H13*N13 + I13*O13, IF(SUM(G13:I13)=2, 1 - PRODUCT( IF(G13=1,1-M13,1), IF(H13=1,1-N13,1), IF(I13=1,1-O13,1) ), IF(SUM(G13:I13)=3, 1 - PRODUCT(1-M13,1-N13,1-O13), 0 ) ) ) ) -> #REF! | Q13: =P13*E13 -> #REF! | R13: =IF(AND(OR(D13="UP",D13="DOWN"), Q13>0.95), D13, 0) -> #REF! | T13: =IF(R13<>0,Configuración!$E$2,0) -> #REF! | U13: =IF(R13<>0,Configuración!$F$2,0) -> #REF! | V13: =IF(R13<>0,Configuración!$G$2,0) -> #REF! | W13: =IF(R13="DOWN",S13+(S13*T13/100),S13-(S13*T13/100)) -> #REF! | X13: =IF(R13="DOWN",S13-(S13*U13/100),S13+(S13*U13/100)) -> #REF! | Z13: =IF(R13="DOWN",IF(Y13 < S13 * (1 - 0.01), Y13 * (1 + 0.005), ""),IF(Y13 > S13 * (1 + 0.01), Y13 * (1 - 0.005), "")) -> #REF! | AB13: =(($B$1) *(T13))/100 -> #REF! | AG13: =IF(R13="DOWN",(S13-AA13)/S13*1000,(AA13-S13)/S13*1000) -> #REF! | AH13: =AB13*(AG13) -> #REF! | AI13: =IF(AK13<V13,"MANTENER","CERRAR") -> #REF!
A14: 45918 | B14: 0.625 | C14: AUDUSD | D14: =IF(COUNTIF(#REF!,"<>NAN")=0, 0, IF(AND(OR(#REF!=#REF!,#REF!="NAN"), OR(#REF!=#REF!,#REF!="NAN"), OR(#REF!=#REF!,#REF!="NAN")),#REF!, 0)) -> #REF! | E14: =IF(#REF!="NAN","",IF( AND(OR(#REF!=#REF!,#REF!="NAN"), OR(#REF!=#REF!,#REF!="NAN"), OR(#REF!=#REF!,#REF!="NAN")), 1, 0)) -> #REF! | G14: =IF(OR(#REF!="UP",#REF!="DOWN"),1,0) -> #REF! | H14: =IF(OR(#REF!="UP",#REF!="DOWN"),1,0) -> #REF! | I14: =IF(OR(#REF!="UP",#REF!="DOWN"),1,0) -> #REF! | M14: =IF(OR(#REF!="UP",#REF!="DOWN"),1,1) -> #REF! | N14: =IF(OR(#REF!="UP",#REF!="DOWN"),VLOOKUP($C14,Configuración!$H$2:$K$11,3),1) -> #REF! | O14: =IF(OR(#REF!="UP",#REF!="DOWN"),VLOOKUP($C14,Configuración!$H$2:$K$11,4),1) -> #REF! | P14: =IF(SUM(G14:I14)=0, 0, IF(SUM(G14:I14)=1, G14*M14 + H14*N14 + I14*O14, IF(SUM(G14:I14)=2, 1 - PRODUCT( IF(G14=1,1-M14,1), IF(H14=1,1-N14,1), IF(I14=1,1-O14,1) ), IF(SUM(G14:I14)=3, 1 - PRODUCT(1-M14,1-N14,1-O14), 0 ) ) ) ) -> #REF! | Q14: =P14*E14 -> #REF! | R14: =IF(AND(OR(D14="UP",D14="DOWN"), Q14>0.95), D14, 0) -> #REF! | T14: =IF(R14<>0,Configuración!$E$2,0) -> #REF! | U14: =IF(R14<>0,Configuración!$F$2,0) -> #REF! | V14: =IF(R14<>0,Configuración!$G$2,0) -> #REF! | W14: =IF(R14="DOWN",S14+(S14*T14/100),S14-(S14*T14/100)) -> #REF! | X14: =IF(R14="DOWN",S14-(S14*U14/100),S14+(S14*U14/100)) -> #REF! | Z14: =IF(R14="DOWN",IF(Y14 < S14 * (1 - 0.01), Y14 * (1 + 0.005), ""),IF(Y14 > S14 * (1 + 0.01), Y14 * (1 - 0.005), "")) -> #REF! | AB14: =(($B$1) *(T14))/100 -> #REF! | AG14: =IF(R14="DOWN",(S14-AA14)/S14*1000,(AA14-S14)/S14*1000) -> #REF! | AH14: =AB14*(AG14) -> #REF! | AI14: =IF(AK14<V14,"MANTENER","CERRAR") -> #REF!
A15: 45918 | B15: 0.625 | C15: CADCHF | D15: =IF(COUNTIF(#REF!,"<>NAN")=0, 0, IF(AND(OR(#REF!=#REF!,#REF!="NAN"), OR(#REF!=#REF!,#REF!="NAN"), OR(#REF!=#REF!,#REF!="NAN")),#REF!, 0)) -> #REF! | E15: =IF(#REF!="NAN","",IF( AND(OR(#REF!=#REF!,#REF!="NAN"), OR(#REF!=#REF!,#REF!="NAN"), OR(#REF!=#REF!,#REF!="NAN")), 1, 0)) -> #REF! | G15: =IF(OR(#REF!="UP",#REF!="DOWN"),1,0) -> #REF! | H15: =IF(OR(#REF!="UP",#REF!="DOWN"),1,0) -> #REF! | I15: =IF(OR(#REF!="UP",#REF!="DOWN"),1,0) -> #REF! | M15: =IF(OR(#REF!="UP",#REF!="DOWN"),1,1) -> #REF! | N15: =IF(OR(#REF!="UP",#REF!="DOWN"),VLOOKUP($C15,Configuración!$H$2:$K$11,3),1) -> #REF! | O15: =IF(OR(#REF!="UP",#REF!="DOWN"),VLOOKUP($C15,Configuración!$H$2:$K$11,4),1) -> #REF! | P15: =IF(SUM(G15:I15)=0, 0, IF(SUM(G15:I15)=1, G15*M15 + H15*N15 + I15*O15, IF(SUM(G15:I15)=2, 1 - PRODUCT( IF(G15=1,1-M15,1), IF(H15=1,1-N15,1), IF(I15=1,1-O15,1) ), IF(SUM(G15:I15)=3, 1 - PRODUCT(1-M15,1-N15,1-O15), 0 ) ) ) ) -> #REF! | Q15: =P15*E15 -> #REF! | R15: =IF(AND(OR(D15="UP",D15="DOWN"), Q15>0.95), D15, 0) -> #REF! | T15: =IF(R15<>0,Configuración!$E$2,0) -> #REF! | U15: =IF(R15<>0,Configuración!$F$2,0) -> #REF! | V15: =IF(R15<>0,Configuración!$G$2,0) -> #REF! | W15: =IF(R15="DOWN",S15+(S15*T15/100),S15-(S15*T15/100)) -> #REF! | X15: =IF(R15="DOWN",S15-(S15*U15/100),S15+(S15*U15/100)) -> #REF! | Z15: =IF(R15="DOWN",IF(Y15 < S15 * (1 - 0.01), Y15 * (1 + 0.005), ""),IF(Y15 > S15 * (1 + 0.01), Y15 * (1 - 0.005), "")) -> #REF! | AB15: =(($B$1) *(T15))/100 -> #REF! | AG15: =IF(R15="DOWN",(S15-AA15)/S15*1000,(AA15-S15)/S15*1000) -> #REF! | AH15: =AB15*(AG15) -> #REF! | AI15: =IF(AK15<V15,"MANTENER","CERRAR") -> #REF!
A16: 45918 | B16: 0.625 | C16: CHFJPY | D16: =IF(COUNTIF(#REF!,"<>NAN")=0, 0, IF(AND(OR(#REF!=#REF!,#REF!="NAN"), OR(#REF!=#REF!,#REF!="NAN"), OR(#REF!=#REF!,#REF!="NAN")),#REF!, 0)) -> #REF! | E16: =IF(#REF!="NAN","",IF( AND(OR(#REF!=#REF!,#REF!="NAN"), OR(#REF!=#REF!,#REF!="NAN"), OR(#REF!=#REF!,#REF!="NAN")), 1, 0)) -> #REF! | G16: =IF(OR(#REF!="UP",#REF!="DOWN"),1,0) -> #REF! | H16: =IF(OR(#REF!="UP",#REF!="DOWN"),1,0) -> #REF! | I16: =IF(OR(#REF!="UP",#REF!="DOWN"),1,0) -> #REF! | M16: =IF(OR(#REF!="UP",#REF!="DOWN"),1,1) -> #REF! | N16: =IF(OR(#REF!="UP",#REF!="DOWN"),VLOOKUP($C16,Configuración!$H$2:$K$11,3),1) -> #REF! | O16: =IF(OR(#REF!="UP",#REF!="DOWN"),VLOOKUP($C16,Configuración!$H$2:$K$11,4),1) -> #REF! | P16: =IF(SUM(G16:I16)=0, 0, IF(SUM(G16:I16)=1, G16*M16 + H16*N16 + I16*O16, IF(SUM(G16:I16)=2, 1 - PRODUCT( IF(G16=1,1-M16,1), IF(H16=1,1-N16,1), IF(I16=1,1-O16,1) ), IF(SUM(G16:I16)=3, 1 - PRODUCT(1-M16,1-N16,1-O16), 0 ) ) ) ) -> #REF! | Q16: =P16*E16 -> #REF! | R16: =IF(AND(OR(D16="UP",D16="DOWN"), Q16>0.95), D16, 0) -> #REF! | T16: =IF(R16<>0,Configuración!$E$2,0) -> #REF! | U16: =IF(R16<>0,Configuración!$F$2,0) -> #REF! | V16: =IF(R16<>0,Configuración!$G$2,0) -> #REF! | W16: =IF(R16="DOWN",S16+(S16*T16/100),S16-(S16*T16/100)) -> #REF! | X16: =IF(R16="DOWN",S16-(S16*U16/100),S16+(S16*U16/100)) -> #REF! | Z16: =IF(R16="DOWN",IF(Y16 < S16 * (1 - 0.01), Y16 * (1 + 0.005), ""),IF(Y16 > S16 * (1 + 0.01), Y16 * (1 - 0.005), "")) -> #REF! | AB16: =(($B$1) *(T16))/100 -> #REF! | AG16: =IF(R16="DOWN",(S16-AA16)/S16*1000,(AA16-S16)/S16*1000) -> #REF! | AH16: =AB16*(AG16) -> #REF! | AI16: =IF(AK16<V16,"MANTENER","CERRAR") -> #REF!
A17: 45918 | B17: 0.625 | C17: EURAUD | D17: =IF(COUNTIF(#REF!,"<>NAN")=0, 0, IF(AND(OR(#REF!=#REF!,#REF!="NAN"), OR(#REF!=#REF!,#REF!="NAN"), OR(#REF!=#REF!,#REF!="NAN")),#REF!, 0)) -> #REF! | E17: =IF(#REF!="NAN","",IF( AND(OR(#REF!=#REF!,#REF!="NAN"), OR(#REF!=#REF!,#REF!="NAN"), OR(#REF!=#REF!,#REF!="NAN")), 1, 0)) -> #REF! | G17: =IF(OR(#REF!="UP",#REF!="DOWN"),1,0) -> #REF! | H17: =IF(OR(#REF!="UP",#REF!="DOWN"),1,0) -> #REF! | I17: =IF(OR(#REF!="UP",#REF!="DOWN"),1,0) -> #REF! | M17: =IF(OR(#REF!="UP",#REF!="DOWN"),1,1) -> #REF! | N17: =IF(OR(#REF!="UP",#REF!="DOWN"),VLOOKUP($C17,Configuración!$H$2:$K$11,3),1) -> #REF! | O17: =IF(OR(#REF!="UP",#REF!="DOWN"),VLOOKUP($C17,Configuración!$H$2:$K$11,4),1) -> #REF! | P17: =IF(SUM(G17:I17)=0, 0, IF(SUM(G17:I17)=1, G17*M17 + H17*N17 + I17*O17, IF(SUM(G17:I17)=2, 1 - PRODUCT( IF(G17=1,1-M17,1), IF(H17=1,1-N17,1), IF(I17=1,1-O17,1) ), IF(SUM(G17:I17)=3, 1 - PRODUCT(1-M17,1-N17,1-O17), 0 ) ) ) ) -> #REF! | Q17: =P17*E17 -> #REF! | R17: =IF(AND(OR(D17="UP",D17="DOWN"), Q17>0.95), D17, 0) -> #REF! | T17: =IF(R17<>0,Configuración!$E$2,0) -> #REF! | U17: =IF(R17<>0,Configuración!$F$2,0) -> #REF! | V17: =IF(R17<>0,Configuración!$G$2,0) -> #REF! | W17: =IF(R17="DOWN",S17+(S17*T17/100),S17-(S17*T17/100)) -> #REF! | X17: =IF(R17="DOWN",S17-(S17*U17/100),S17+(S17*U17/100)) -> #REF! | Z17: =IF(R17="DOWN",IF(Y17 < S17 * (1 - 0.01), Y17 * (1 + 0.005), ""),IF(Y17 > S17 * (1 + 0.01), Y17 * (1 - 0.005), "")) -> #REF! | AB17: =(($B$1) *(T17))/100 -> #REF! | AG17: =IF(R17="DOWN",(S17-AA17)/S17*1000,(AA17-S17)/S17*1000) -> #REF! | AH17: =AB17*(AG17) -> #REF! | AI17: =IF(AK17<V17,"MANTENER","CERRAR") -> #REF!
A18: 45918 | B18: 0.625 | C18: AUDUSD | D18: =IF(COUNTIF(#REF!,"<>NAN")=0, 0, IF(AND(OR(#REF!=#REF!,#REF!="NAN"), OR(#REF!=#REF!,#REF!="NAN"), OR(#REF!=#REF!,#REF!="NAN")),#REF!, 0)) -> #REF! | E18: =IF(#REF!="NAN","",IF( AND(OR(#REF!=#REF!,#REF!="NAN"), OR(#REF!=#REF!,#REF!="NAN"), OR(#REF!=#REF!,#REF!="NAN")), 1, 0)) -> #REF! | G18: =IF(OR(#REF!="UP",#REF!="DOWN"),1,0) -> #REF! | H18: =IF(OR(#REF!="UP",#REF!="DOWN"),1,0) -> #REF! | I18: =IF(OR(#REF!="UP",#REF!="DOWN"),1,0) -> #REF! | M18: =IF(OR(#REF!="UP",#REF!="DOWN"),1,1) -> #REF! | N18: =IF(OR(#REF!="UP",#REF!="DOWN"),VLOOKUP($C18,Configuración!$H$2:$K$11,3),1) -> #REF! | O18: =IF(OR(#REF!="UP",#REF!="DOWN"),VLOOKUP($C18,Configuración!$H$2:$K$11,4),1) -> #REF! | P18: =IF(SUM(G18:I18)=0, 0, IF(SUM(G18:I18)=1, G18*M18 + H18*N18 + I18*O18, IF(SUM(G18:I18)=2, 1 - PRODUCT( IF(G18=1,1-M18,1), IF(H18=1,1-N18,1), IF(I18=1,1-O18,1) ), IF(SUM(G18:I18)=3, 1 - PRODUCT(1-M18,1-N18,1-O18), 0 ) ) ) ) -> #REF! | Q18: =P18*E18 -> #REF! | R18: =IF(AND(OR(D18="UP",D18="DOWN"), Q18>0.95), D18, 0) -> #REF! | T18: =IF(R18<>0,Configuración!$E$2,0) -> #REF! | U18: =IF(R18<>0,Configuración!$F$2,0) -> #REF! | V18: =IF(R18<>0,Configuración!$G$2,0) -> #REF! | W18: =IF(R18="DOWN",S18+(S18*T18/100),S18-(S18*T18/100)) -> #REF! | X18: =IF(R18="DOWN",S18-(S18*U18/100),S18+(S18*U18/100)) -> #REF! | Z18: =IF(R18="DOWN",IF(Y18 < S18 * (1 - 0.01), Y18 * (1 + 0.005), ""),IF(Y18 > S18 * (1 + 0.01), Y18 * (1 - 0.005), "")) -> #REF! | AB18: =(($B$1) *(T18))/100 -> #REF! | AG18: =IF(R18="DOWN",(S18-AA18)/S18*1000,(AA18-S18)/S18*1000) -> #REF! | AH18: =AB18*(AG18) -> #REF! | AI18: =IF(AK18<V18,"MANTENER","CERRAR") -> #REF!
A19: 45918 | B19: 0.625 | C19: GBPUSD | D19: =IF(COUNTIF(#REF!,"<>NAN")=0, 0, IF(AND(OR(#REF!=#REF!,#REF!="NAN"), OR(#REF!=#REF!,#REF!="NAN"), OR(#REF!=#REF!,#REF!="NAN")),#REF!, 0)) -> #REF! | E19: =IF(#REF!="NAN","",IF( AND(OR(#REF!=#REF!,#REF!="NAN"), OR(#REF!=#REF!,#REF!="NAN"), OR(#REF!=#REF!,#REF!="NAN")), 1, 0)) -> #REF! | G19: =IF(OR(#REF!="UP",#REF!="DOWN"),1,0) -> #REF! | H19: =IF(OR(#REF!="UP",#REF!="DOWN"),1,0) -> #REF! | I19: =IF(OR(#REF!="UP",#REF!="DOWN"),1,0) -> #REF! | M19: =IF(OR(#REF!="UP",#REF!="DOWN"),1,1) -> #REF! | N19: =IF(OR(#REF!="UP",#REF!="DOWN"),VLOOKUP($C19,Configuración!$H$2:$K$11,3),1) -> #REF! | O19: =IF(OR(#REF!="UP",#REF!="DOWN"),VLOOKUP($C19,Configuración!$H$2:$K$11,4),1) -> #REF! | P19: =IF(SUM(G19:I19)=0, 0, IF(SUM(G19:I19)=1, G19*M19 + H19*N19 + I19*O19, IF(SUM(G19:I19)=2, 1 - PRODUCT( IF(G19=1,1-M19,1), IF(H19=1,1-N19,1), IF(I19=1,1-O19,1) ), IF(SUM(G19:I19)=3, 1 - PRODUCT(1-M19,1-N19,1-O19), 0 ) ) ) ) -> #REF! | Q19: =P19*E19 -> #REF! | R19: =IF(AND(OR(D19="UP",D19="DOWN"), Q19>0.95), D19, 0) -> #REF! | T19: =IF(R19<>0,Configuración!$E$2,0) -> #REF! | U19: =IF(R19<>0,Configuración!$F$2,0) -> #REF! | V19: =IF(R19<>0,Configuración!$G$2,0) -> #REF! | W19: =IF(R19="DOWN",S19+(S19*T19/100),S19-(S19*T19/100)) -> #REF! | X19: =IF(R19="DOWN",S19-(S19*U19/100),S19+(S19*U19/100)) -> #REF! | Z19: =IF(R19="DOWN",IF(Y19 < S19 * (1 - 0.01), Y19 * (1 + 0.005), ""),IF(Y19 > S19 * (1 + 0.01), Y19 * (1 - 0.005), "")) -> #REF! | AB19: =(($B$1) *(T19))/100 -> #REF! | AG19: =IF(R19="DOWN",(S19-AA19)/S19*1000,(AA19-S19)/S19*1000) -> #REF! | AH19: =AB19*(AG19) -> #REF! | AI19: =IF(AK19<V19,"MANTENER","CERRAR") -> #REF!
A20: 45918 | B20: 0.625 | C20: USDCAD | D20: =IF(COUNTIF(#REF!,"<>NAN")=0, 0, IF(AND(OR(#REF!=#REF!,#REF!="NAN"), OR(#REF!=#REF!,#REF!="NAN"), OR(#REF!=#REF!,#REF!="NAN")),#REF!, 0)) -> #REF! | E20: =IF(#REF!="NAN","",IF( AND(OR(#REF!=#REF!,#REF!="NAN"), OR(#REF!=#REF!,#REF!="NAN"), OR(#REF!=#REF!,#REF!="NAN")), 1, 0)) -> #REF! | G20: =IF(OR(#REF!="UP",#REF!="DOWN"),1,0) -> #REF! | H20: =IF(OR(#REF!="UP",#REF!="DOWN"),1,0) -> #REF! | I20: =IF(OR(#REF!="UP",#REF!="DOWN"),1,0) -> #REF! | M20: =IF(OR(#REF!="UP",#REF!="DOWN"),1,1) -> #REF! | N20: =IF(OR(#REF!="UP",#REF!="DOWN"),VLOOKUP($C20,Configuración!$H$2:$K$11,3),1) -> #REF! | O20: =IF(OR(#REF!="UP",#REF!="DOWN"),VLOOKUP($C20,Configuración!$H$2:$K$11,4),1) -> #REF! | P20: =IF(SUM(G20:I20)=0, 0, IF(SUM(G20:I20)=1, G20*M20 + H20*N20 + I20*O20, IF(SUM(G20:I20)=2, 1 - PRODUCT( IF(G20=1,1-M20,1), IF(H20=1,1-N20,1), IF(I20=1,1-O20,1) ), IF(SUM(G20:I20)=3, 1 - PRODUCT(1-M20,1-N20,1-O20), 0 ) ) ) ) -> #REF! | Q20: =P20*E20 -> #REF! | R20: =IF(AND(OR(D20="UP",D20="DOWN"), Q20>0.95), D20, 0) -> #REF! | T20: =IF(R20<>0,Configuración!$E$2,0) -> #REF! | U20: =IF(R20<>0,Configuración!$F$2,0) -> #REF! | V20: =IF(R20<>0,Configuración!$G$2,0) -> #REF! | W20: =IF(R20="DOWN",S20+(S20*T20/100),S20-(S20*T20/100)) -> #REF! | X20: =IF(R20="DOWN",S20-(S20*U20/100),S20+(S20*U20/100)) -> #REF! | Z20: =IF(R20="DOWN",IF(Y20 < S20 * (1 - 0.01), Y20 * (1 + 0.005), ""),IF(Y20 > S20 * (1 + 0.01), Y20 * (1 - 0.005), "")) -> #REF! | AB20: =(($B$1) *(T20))/100 -> #REF! | AG20: =IF(R20="DOWN",(S20-AA20)/S20*1000,(AA20-S20)/S20*1000) -> #REF! | AH20: =AB20*(AG20) -> #REF! | AI20: =IF(AK20<V20,"MANTENER","CERRAR") -> #REF!
A21: 45918 | B21: 0.625 | C21: USDCHF | D21: =IF(COUNTIF(#REF!,"<>NAN")=0, 0, IF(AND(OR(#REF!=#REF!,#REF!="NAN"), OR(#REF!=#REF!,#REF!="NAN"), OR(#REF!=#REF!,#REF!="NAN")),#REF!, 0)) -> #REF! | E21: =IF(#REF!="NAN","",IF( AND(OR(#REF!=#REF!,#REF!="NAN"), OR(#REF!=#REF!,#REF!="NAN"), OR(#REF!=#REF!,#REF!="NAN")), 1, 0)) -> #REF! | G21: =IF(OR(#REF!="UP",#REF!="DOWN"),1,0) -> #REF! | H21: =IF(OR(#REF!="UP",#REF!="DOWN"),1,0) -> #REF! | I21: =IF(OR(#REF!="UP",#REF!="DOWN"),1,0) -> #REF! | M21: =IF(OR(#REF!="UP",#REF!="DOWN"),1,1) -> #REF! | N21: =IF(OR(#REF!="UP",#REF!="DOWN"),VLOOKUP($C21,Configuración!$H$2:$K$11,3),1) -> #REF! | O21: =IF(OR(#REF!="UP",#REF!="DOWN"),VLOOKUP($C21,Configuración!$H$2:$K$11,4),1) -> #REF! | P21: =IF(SUM(G21:I21)=0, 0, IF(SUM(G21:I21)=1, G21*M21 + H21*N21 + I21*O21, IF(SUM(G21:I21)=2, 1 - PRODUCT( IF(G21=1,1-M21,1), IF(H21=1,1-N21,1), IF(I21=1,1-O21,1) ), IF(SUM(G21:I21)=3, 1 - PRODUCT(1-M21,1-N21,1-O21), 0 ) ) ) ) -> #REF! | Q21: =P21*E21 -> #REF! | R21: =IF(AND(OR(D21="UP",D21="DOWN"), Q21>0.95), D21, 0) -> #REF! | S21: 0.78961 | T21: =IF(R21<>0,Configuración!$E$2,0) -> #REF! | U21: =IF(R21<>0,Configuración!$F$2,0) -> #REF! | V21: =IF(R21<>0,Configuración!$G$2,0) -> #REF! | W21: =IF(R21="DOWN",S21+(S21*T21/100),S21-(S21*T21/100)) -> #REF! | X21: =IF(R21="DOWN",S21-(S21*U21/100),S21+(S21*U21/100)) -> #REF! | Z21: =IF(R21="DOWN",IF(Y21 < S21 * (1 - 0.01), Y21 * (1 + 0.005), ""),IF(Y21 > S21 * (1 + 0.01), Y21 * (1 - 0.005), "")) -> #REF! | AB21: =(($B$1) *(T21))/100 -> #REF! | AG21: =IF(R21="DOWN",(S21-AA21)/S21*1000,(AA21-S21)/S21*1000) -> #REF! | AH21: =AB21*(AG21) -> #REF! | AI21: =IF(AK21<V21,"MANTENER","CERRAR") -> #REF!
A22: 45918 | B22: 0.625 | C22: USDJPY | D22: =IF(COUNTIF(#REF!,"<>NAN")=0, 0, IF(AND(OR(#REF!=#REF!,#REF!="NAN"), OR(#REF!=#REF!,#REF!="NAN"), OR(#REF!=#REF!,#REF!="NAN")),#REF!, 0)) -> #REF! | E22: =IF(#REF!="NAN","",IF( AND(OR(#REF!=#REF!,#REF!="NAN"), OR(#REF!=#REF!,#REF!="NAN"), OR(#REF!=#REF!,#REF!="NAN")), 1, 0)) -> #REF! | G22: =IF(OR(#REF!="UP",#REF!="DOWN"),1,0) -> #REF! | H22: =IF(OR(#REF!="UP",#REF!="DOWN"),1,0) -> #REF! | I22: =IF(OR(#REF!="UP",#REF!="DOWN"),1,0) -> #REF! | M22: =IF(OR(#REF!="UP",#REF!="DOWN"),1,1) -> #REF! | N22: =IF(OR(#REF!="UP",#REF!="DOWN"),VLOOKUP($C22,Configuración!$H$2:$K$11,3),1) -> #REF! | O22: =IF(OR(#REF!="UP",#REF!="DOWN"),VLOOKUP($C22,Configuración!$H$2:$K$11,4),1) -> #REF! | P22: =IF(SUM(G22:I22)=0, 0, IF(SUM(G22:I22)=1, G22*M22 + H22*N22 + I22*O22, IF(SUM(G22:I22)=2, 1 - PRODUCT( IF(G22=1,1-M22,1), IF(H22=1,1-N22,1), IF(I22=1,1-O22,1) ), IF(SUM(G22:I22)=3, 1 - PRODUCT(1-M22,1-N22,1-O22), 0 ) ) ) ) -> #REF! | Q22: =P22*E22 -> #REF! | R22: =IF(AND(OR(D22="UP",D22="DOWN"), Q22>0.95), D22, 0) -> #REF! | T22: =IF(R22<>0,Configuración!$E$2,0) -> #REF! | U22: =IF(R22<>0,Configuración!$F$2,0) -> #REF! | V22: =IF(R22<>0,Configuración!$G$2,0) -> #REF! | W22: =IF(R22="DOWN",S22+(S22*T22/100),S22-(S22*T22/100)) -> #REF! | X22: =IF(R22="DOWN",S22-(S22*U22/100),S22+(S22*U22/100)) -> #REF! | Z22: =IF(R22="DOWN",IF(Y22 < S22 * (1 - 0.01), Y22 * (1 + 0.005), ""),IF(Y22 > S22 * (1 + 0.01), Y22 * (1 - 0.005), "")) -> #REF! | AB22: =(($B$1) *(T22))/100 -> #REF! | AG22: =IF(R22="DOWN",(S22-AA22)/S22*1000,(AA22-S22)/S22*1000) -> #REF! | AH22: =AB22*(AG22) -> #REF! | AI22: =IF(AK22<V22,"MANTENER","CERRAR") -> #REF!
A23: 45919 | B23: 0.625 | C23: AUDCAD | D23: =IF(COUNTIF(#REF!,"<>NAN")=0, 0, IF(AND(OR(#REF!=#REF!,#REF!="NAN"), OR(#REF!=#REF!,#REF!="NAN"), OR(#REF!=#REF!,#REF!="NAN")),#REF!, 0)) -> #REF! | E23: =IF(#REF!="NAN","",IF( AND(OR(#REF!=#REF!,#REF!="NAN"), OR(#REF!=#REF!,#REF!="NAN"), OR(#REF!=#REF!,#REF!="NAN")), 1, 0)) -> #REF! | G23: =IF(OR(#REF!="UP",#REF!="DOWN"),1,0) -> #REF! | H23: =IF(OR(#REF!="UP",#REF!="DOWN"),1,0) -> #REF! | I23: =IF(OR(#REF!="UP",#REF!="DOWN"),1,0) -> #REF! | M23: =IF(OR(#REF!="UP",#REF!="DOWN"),1,1) -> #REF! | N23: =IF(OR(#REF!="UP",#REF!="DOWN"),VLOOKUP($C23,Configuración!$H$2:$K$11,3),1) -> #REF! | O23: =IF(OR(#REF!="UP",#REF!="DOWN"),VLOOKUP($C23,Configuración!$H$2:$K$11,4),1) -> #REF! | P23: =IF(SUM(G23:I23)=0, 0, IF(SUM(G23:I23)=1, G23*M23 + H23*N23 + I23*O23, IF(SUM(G23:I23)=2, 1 - PRODUCT( IF(G23=1,1-M23,1), IF(H23=1,1-N23,1), IF(I23=1,1-O23,1) ), IF(SUM(G23:I23)=3, 1 - PRODUCT(1-M23,1-N23,1-O23), 0 ) ) ) ) -> #REF! | Q23: =P23*E23 -> #REF! | R23: =IF(AND(OR(D23="UP",D23="DOWN"), Q23>0.95), D23, 0) -> #REF! | T23: =IF(R23<>0,Configuración!$E$2,0) -> #REF! | U23: =IF(R23<>0,Configuración!$F$2,0) -> #REF! | V23: =IF(R23<>0,Configuración!$G$2,0) -> #REF! | W23: =IF(R23="DOWN",S23+(S23*T23/100),S23-(S23*T23/100)) -> #REF! | X23: =IF(R23="DOWN",S23-(S23*U23/100),S23+(S23*U23/100)) -> #REF! | Z23: =IF(R23="DOWN",IF(Y23 < S23 * (1 - 0.01), Y23 * (1 + 0.005), ""),IF(Y23 > S23 * (1 + 0.01), Y23 * (1 - 0.005), "")) -> #REF! | AB23: =(($B$1) *(T23))/100 -> #REF! | AG23: =IF(R23="DOWN",(S23-AA23)/S23*1000,(AA23-S23)/S23*1000) -> #REF! | AH23: =AB23*(AG23) -> #REF! | AI23: =IF(AK23<V23,"MANTENER","CERRAR") -> #REF!
A24: 45919 | B24: 0.625 | C24: AUDUSD | D24: =IF(COUNTIF(#REF!,"<>NAN")=0, 0, IF(AND(OR(#REF!=#REF!,#REF!="NAN"), OR(#REF!=#REF!,#REF!="NAN"), OR(#REF!=#REF!,#REF!="NAN")),#REF!, 0)) -> #REF! | E24: =IF(#REF!="NAN","",IF( AND(OR(#REF!=#REF!,#REF!="NAN"), OR(#REF!=#REF!,#REF!="NAN"), OR(#REF!=#REF!,#REF!="NAN")), 1, 0)) -> #REF! | G24: =IF(OR(#REF!="UP",#REF!="DOWN"),1,0) -> #REF! | H24: =IF(OR(#REF!="UP",#REF!="DOWN"),1,0) -> #REF! | I24: =IF(OR(#REF!="UP",#REF!="DOWN"),1,0) -> #REF! | M24: =IF(OR(#REF!="UP",#REF!="DOWN"),1,1) -> #REF! | N24: =IF(OR(#REF!="UP",#REF!="DOWN"),VLOOKUP($C24,Configuración!$H$2:$K$11,3),1) -> #REF! | O24: =IF(OR(#REF!="UP",#REF!="DOWN"),VLOOKUP($C24,Configuración!$H$2:$K$11,4),1) -> #REF! | P24: =IF(SUM(G24:I24)=0, 0, IF(SUM(G24:I24)=1, G24*M24 + H24*N24 + I24*O24, IF(SUM(G24:I24)=2, 1 - PRODUCT( IF(G24=1,1-M24,1), IF(H24=1,1-N24,1), IF(I24=1,1-O24,1) ), IF(SUM(G24:I24)=3, 1 - PRODUCT(1-M24,1-N24,1-O24), 0 ) ) ) ) -> #REF! | Q24: =P24*E24 -> #REF! | R24: =IF(AND(OR(D24="UP",D24="DOWN"), Q24>0.95), D24, 0) -> #REF! | T24: =IF(R24<>0,Configuración!$E$2,0) -> #REF! | U24: =IF(R24<>0,Configuración!$F$2,0) -> #REF! | V24: =IF(R24<>0,Configuración!$G$2,0) -> #REF! | W24: =IF(R24="DOWN",S24+(S24*T24/100),S24-(S24*T24/100)) -> #REF! | X24: =IF(R24="DOWN",S24-(S24*U24/100),S24+(S24*U24/100)) -> #REF! | Z24: =IF(R24="DOWN",IF(Y24 < S24 * (1 - 0.01), Y24 * (1 + 0.005), ""),IF(Y24 > S24 * (1 + 0.01), Y24 * (1 - 0.005), "")) -> #REF! | AB24: =(($B$1) *(T24))/100 -> #REF! | AG24: =IF(R24="DOWN",(S24-AA24)/S24*1000,(AA24-S24)/S24*1000) -> #REF! | AH24: =AB24*(AG24) -> #REF! | AI24: =IF(AK24<V24,"MANTENER","CERRAR") -> #REF!
A25: 45919 | B25: 0.625 | C25: CADCHF | D25: =IF(COUNTIF(#REF!,"<>NAN")=0, 0, IF(AND(OR(#REF!=#REF!,#REF!="NAN"), OR(#REF!=#REF!,#REF!="NAN"), OR(#REF!=#REF!,#REF!="NAN")),#REF!, 0)) -> #REF! | E25: =IF(#REF!="NAN","",IF( AND(OR(#REF!=#REF!,#REF!="NAN"), OR(#REF!=#REF!,#REF!="NAN"), OR(#REF!=#REF!,#REF!="NAN")), 1, 0)) -> #REF! | G25: =IF(OR(#REF!="UP",#REF!="DOWN"),1,0) -> #REF! | H25: =IF(OR(#REF!="UP",#REF!="DOWN"),1,0) -> #REF! | I25: =IF(OR(#REF!="UP",#REF!="DOWN"),1,0) -> #REF! | M25: =IF(OR(#REF!="UP",#REF!="DOWN"),1,1) -> #REF! | N25: =IF(OR(#REF!="UP",#REF!="DOWN"),VLOOKUP($C25,Configuración!$H$2:$K$11,3),1) -> #REF! | O25: =IF(OR(#REF!="UP",#REF!="DOWN"),VLOOKUP($C25,Configuración!$H$2:$K$11,4),1) -> #REF! | P25: =IF(SUM(G25:I25)=0, 0, IF(SUM(G25:I25)=1, G25*M25 + H25*N25 + I25*O25, IF(SUM(G25:I25)=2, 1 - PRODUCT( IF(G25=1,1-M25,1), IF(H25=1,1-N25,1), IF(I25=1,1-O25,1) ), IF(SUM(G25:I25)=3, 1 - PRODUCT(1-M25,1-N25,1-O25), 0 ) ) ) ) -> #REF! | Q25: =P25*E25 -> #REF! | R25: =IF(AND(OR(D25="UP",D25="DOWN"), Q25>0.95), D25, 0) -> #REF! | T25: =IF(R25<>0,Configuración!$E$2,0) -> #REF! | U25: =IF(R25<>0,Configuración!$F$2,0) -> #REF! | V25: =IF(R25<>0,Configuración!$G$2,0) -> #REF! | W25: =IF(R25="DOWN",S25+(S25*T25/100),S25-(S25*T25/100)) -> #REF! | X25: =IF(R25="DOWN",S25-(S25*U25/100),S25+(S25*U25/100)) -> #REF! | Z25: =IF(R25="DOWN",IF(Y25 < S25 * (1 - 0.01), Y25 * (1 + 0.005), ""),IF(Y25 > S25 * (1 + 0.01), Y25 * (1 - 0.005), "")) -> #REF! | AB25: =(($B$1) *(T25))/100 -> #REF! | AG25: =IF(R25="DOWN",(S25-AA25)/S25*1000,(AA25-S25)/S25*1000) -> #REF! | AH25: =AB25*(AG25) -> #REF! | AI25: =IF(AK25<V25,"MANTENER","CERRAR") -> #REF!
A26: 45919 | B26: 0.625 | C26: CHFJPY | D26: =IF(COUNTIF(#REF!,"<>NAN")=0, 0, IF(AND(OR(#REF!=#REF!,#REF!="NAN"), OR(#REF!=#REF!,#REF!="NAN"), OR(#REF!=#REF!,#REF!="NAN")),#REF!, 0)) -> #REF! | E26: =IF(#REF!="NAN","",IF( AND(OR(#REF!=#REF!,#REF!="NAN"), OR(#REF!=#REF!,#REF!="NAN"), OR(#REF!=#REF!,#REF!="NAN")), 1, 0)) -> #REF! | G26: =IF(OR(#REF!="UP",#REF!="DOWN"),1,0) -> #REF! | H26: =IF(OR(#REF!="UP",#REF!="DOWN"),1,0) -> #REF! | I26: =IF(OR(#REF!="UP",#REF!="DOWN"),1,0) -> #REF! | M26: =IF(OR(#REF!="UP",#REF!="DOWN"),1,1) -> #REF! | N26: =IF(OR(#REF!="UP",#REF!="DOWN"),VLOOKUP($C26,Configuración!$H$2:$K$11,3),1) -> #REF! | O26: =IF(OR(#REF!="UP",#REF!="DOWN"),VLOOKUP($C26,Configuración!$H$2:$K$11,4),1) -> #REF! | P26: =IF(SUM(G26:I26)=0, 0, IF(SUM(G26:I26)=1, G26*M26 + H26*N26 + I26*O26, IF(SUM(G26:I26)=2, 1 - PRODUCT( IF(G26=1,1-M26,1), IF(H26=1,1-N26,1), IF(I26=1,1-O26,1) ), IF(SUM(G26:I26)=3, 1 - PRODUCT(1-M26,1-N26,1-O26), 0 ) ) ) ) -> #REF! | Q26: =P26*E26 -> #REF! | R26: =IF(AND(OR(D26="UP",D26="DOWN"), Q26>0.95), D26, 0) -> #REF! | T26: =IF(R26<>0,Configuración!$E$2,0) -> #REF! | U26: =IF(R26<>0,Configuración!$F$2,0) -> #REF! | V26: =IF(R26<>0,Configuración!$G$2,0) -> #REF! | W26: =IF(R26="DOWN",S26+(S26*T26/100),S26-(S26*T26/100)) -> #REF! | X26: =IF(R26="DOWN",S26-(S26*U26/100),S26+(S26*U26/100)) -> #REF! | Z26: =IF(R26="DOWN",IF(Y26 < S26 * (1 - 0.01), Y26 * (1 + 0.005), ""),IF(Y26 > S26 * (1 + 0.01), Y26 * (1 - 0.005), "")) -> #REF! | AB26: =(($B$1) *(T26))/100 -> #REF! | AG26: =IF(R26="DOWN",(S26-AA26)/S26*1000,(AA26-S26)/S26*1000) -> #REF! | AH26: =AB26*(AG26) -> #REF! | AI26: =IF(AK26<V26,"MANTENER","CERRAR") -> #REF!
A27: 45919 | B27: 0.625 | C27: EURAUD | D27: =IF(COUNTIF(#REF!,"<>NAN")=0, 0, IF(AND(OR(#REF!=#REF!,#REF!="NAN"), OR(#REF!=#REF!,#REF!="NAN"), OR(#REF!=#REF!,#REF!="NAN")),#REF!, 0)) -> #REF! | E27: =IF(#REF!="NAN","",IF( AND(OR(#REF!=#REF!,#REF!="NAN"), OR(#REF!=#REF!,#REF!="NAN"), OR(#REF!=#REF!,#REF!="NAN")), 1, 0)) -> #REF! | G27: =IF(OR(#REF!="UP",#REF!="DOWN"),1,0) -> #REF! | H27: =IF(OR(#REF!="UP",#REF!="DOWN"),1,0) -> #REF! | I27: =IF(OR(#REF!="UP",#REF!="DOWN"),1,0) -> #REF! | M27: =IF(OR(#REF!="UP",#REF!="DOWN"),1,1) -> #REF! | N27: =IF(OR(#REF!="UP",#REF!="DOWN"),VLOOKUP($C27,Configuración!$H$2:$K$11,3),1) -> #REF! | O27: =IF(OR(#REF!="UP",#REF!="DOWN"),VLOOKUP($C27,Configuración!$H$2:$K$11,4),1) -> #REF! | P27: =IF(SUM(G27:I27)=0, 0, IF(SUM(G27:I27)=1, G27*M27 + H27*N27 + I27*O27, IF(SUM(G27:I27)=2, 1 - PRODUCT( IF(G27=1,1-M27,1), IF(H27=1,1-N27,1), IF(I27=1,1-O27,1) ), IF(SUM(G27:I27)=3, 1 - PRODUCT(1-M27,1-N27,1-O27), 0 ) ) ) ) -> #REF! | Q27: =P27*E27 -> #REF! | R27: =IF(AND(OR(D27="UP",D27="DOWN"), Q27>0.95), D27, 0) -> #REF! | T27: =IF(R27<>0,Configuración!$E$2,0) -> #REF! | U27: =IF(R27<>0,Configuración!$F$2,0) -> #REF! | V27: =IF(R27<>0,Configuración!$G$2,0) -> #REF! | W27: =IF(R27="DOWN",S27+(S27*T27/100),S27-(S27*T27/100)) -> #REF! | X27: =IF(R27="DOWN",S27-(S27*U27/100),S27+(S27*U27/100)) -> #REF! | Z27: =IF(R27="DOWN",IF(Y27 < S27 * (1 - 0.01), Y27 * (1 + 0.005), ""),IF(Y27 > S27 * (1 + 0.01), Y27 * (1 - 0.005), "")) -> #REF! | AB27: =(($B$1) *(T27))/100 -> #REF! | AG27: =IF(R27="DOWN",(S27-AA27)/S27*1000,(AA27-S27)/S27*1000) -> #REF! | AH27: =AB27*(AG27) -> #REF! | AI27: =IF(AK27<V27,"MANTENER","CERRAR") -> #REF!
A28: 45919 | B28: 0.625 | C28: EURUSD | D28: =IF(COUNTIF(#REF!,"<>NAN")=0, 0, IF(AND(OR(#REF!=#REF!,#REF!="NAN"), OR(#REF!=#REF!,#REF!="NAN"), OR(#REF!=#REF!,#REF!="NAN")),#REF!, 0)) -> #REF! | E28: =IF(#REF!="NAN","",IF( AND(OR(#REF!=#REF!,#REF!="NAN"), OR(#REF!=#REF!,#REF!="NAN"), OR(#REF!=#REF!,#REF!="NAN")), 1, 0)) -> #REF! | G28: =IF(OR(#REF!="UP",#REF!="DOWN"),1,0) -> #REF! | H28: =IF(OR(#REF!="UP",#REF!="DOWN"),1,0) -> #REF! | I28: =IF(OR(#REF!="UP",#REF!="DOWN"),1,0) -> #REF! | M28: =IF(OR(#REF!="UP",#REF!="DOWN"),1,1) -> #REF! | N28: =IF(OR(#REF!="UP",#REF!="DOWN"),VLOOKUP($C28,Configuración!$H$2:$K$11,3),1) -> #REF! | O28: =IF(OR(#REF!="UP",#REF!="DOWN"),VLOOKUP($C28,Configuración!$H$2:$K$11,4),1) -> #REF! | P28: =IF(SUM(G28:I28)=0, 0, IF(SUM(G28:I28)=1, G28*M28 + H28*N28 + I28*O28, IF(SUM(G28:I28)=2, 1 - PRODUCT( IF(G28=1,1-M28,1), IF(H28=1,1-N28,1), IF(I28=1,1-O28,1) ), IF(SUM(G28:I28)=3, 1 - PRODUCT(1-M28,1-N28,1-O28), 0 ) ) ) ) -> #REF! | Q28: =P28*E28 -> #REF! | R28: =IF(AND(OR(D28="UP",D28="DOWN"), Q28>0.95), D28, 0) -> #REF! | T28: =IF(R28<>0,Configuración!$E$2,0) -> #REF! | U28: =IF(R28<>0,Configuración!$F$2,0) -> #REF! | V28: =IF(R28<>0,Configuración!$G$2,0) -> #REF! | W28: =IF(R28="DOWN",S28+(S28*T28/100),S28-(S28*T28/100)) -> #REF! | X28: =IF(R28="DOWN",S28-(S28*U28/100),S28+(S28*U28/100)) -> #REF! | Z28: =IF(R28="DOWN",IF(Y28 < S28 * (1 - 0.01), Y28 * (1 + 0.005), ""),IF(Y28 > S28 * (1 + 0.01), Y28 * (1 - 0.005), "")) -> #REF! | AB28: =(($B$1) *(T28))/100 -> #REF! | AG28: =IF(R28="DOWN",(S28-AA28)/S28*1000,(AA28-S28)/S28*1000) -> #REF! | AH28: =AB28*(AG28) -> #REF! | AI28: =IF(AK28<V28,"MANTENER","CERRAR") -> #REF!
A29: 45919 | B29: 0.625 | C29: GBPUSD | D29: =IF(COUNTIF(#REF!,"<>NAN")=0, 0, IF(AND(OR(#REF!=#REF!,#REF!="NAN"), OR(#REF!=#REF!,#REF!="NAN"), OR(#REF!=#REF!,#REF!="NAN")),#REF!, 0)) -> #REF! | E29: =IF(#REF!="NAN","",IF( AND(OR(#REF!=#REF!,#REF!="NAN"), OR(#REF!=#REF!,#REF!="NAN"), OR(#REF!=#REF!,#REF!="NAN")), 1, 0)) -> #REF! | G29: =IF(OR(#REF!="UP",#REF!="DOWN"),1,0) -> #REF! | H29: =IF(OR(#REF!="UP",#REF!="DOWN"),1,0) -> #REF! | I29: =IF(OR(#REF!="UP",#REF!="DOWN"),1,0) -> #REF! | M29: =IF(OR(#REF!="UP",#REF!="DOWN"),1,1) -> #REF! | N29: =IF(OR(#REF!="UP",#REF!="DOWN"),VLOOKUP($C29,Configuración!$H$2:$K$11,3),1) -> #REF! | O29: =IF(OR(#REF!="UP",#REF!="DOWN"),VLOOKUP($C29,Configuración!$H$2:$K$11,4),1) -> #REF! | P29: =IF(SUM(G29:I29)=0, 0, IF(SUM(G29:I29)=1, G29*M29 + H29*N29 + I29*O29, IF(SUM(G29:I29)=2, 1 - PRODUCT( IF(G29=1,1-M29,1), IF(H29=1,1-N29,1), IF(I29=1,1-O29,1) ), IF(SUM(G29:I29)=3, 1 - PRODUCT(1-M29,1-N29,1-O29), 0 ) ) ) ) -> #REF! | Q29: =P29*E29 -> #REF! | R29: =IF(AND(OR(D29="UP",D29="DOWN"), Q29>0.95), D29, 0) -> #REF! | T29: =IF(R29<>0,Configuración!$E$2,0) -> #REF! | U29: =IF(R29<>0,Configuración!$F$2,0) -> #REF! | V29: =IF(R29<>0,Configuración!$G$2,0) -> #REF! | W29: =IF(R29="DOWN",S29+(S29*T29/100),S29-(S29*T29/100)) -> #REF! | X29: =IF(R29="DOWN",S29-(S29*U29/100),S29+(S29*U29/100)) -> #REF! | Z29: =IF(R29="DOWN",IF(Y29 < S29 * (1 - 0.01), Y29 * (1 + 0.005), ""),IF(Y29 > S29 * (1 + 0.01), Y29 * (1 - 0.005), "")) -> #REF! | AB29: =(($B$1) *(T29))/100 -> #REF! | AG29: =IF(R29="DOWN",(S29-AA29)/S29*1000,(AA29-S29)/S29*1000) -> #REF! | AH29: =AB29*(AG29) -> #REF! | AI29: =IF(AK29<V29,"MANTENER","CERRAR") -> #REF!
A30: 45919 | B30: 0.625 | C30: USDCAD | D30: =IF(COUNTIF(#REF!,"<>NAN")=0, 0, IF(AND(OR(#REF!=#REF!,#REF!="NAN"), OR(#REF!=#REF!,#REF!="NAN"), OR(#REF!=#REF!,#REF!="NAN")),#REF!, 0)) -> #REF! | E30: =IF(#REF!="NAN","",IF( AND(OR(#REF!=#REF!,#REF!="NAN"), OR(#REF!=#REF!,#REF!="NAN"), OR(#REF!=#REF!,#REF!="NAN")), 1, 0)) -> #REF! | G30: =IF(OR(#REF!="UP",#REF!="DOWN"),1,0) -> #REF! | H30: =IF(OR(#REF!="UP",#REF!="DOWN"),1,0) -> #REF! | I30: =IF(OR(#REF!="UP",#REF!="DOWN"),1,0) -> #REF! | M30: =IF(OR(#REF!="UP",#REF!="DOWN"),1,1) -> #REF! | N30: =IF(OR(#REF!="UP",#REF!="DOWN"),VLOOKUP($C30,Configuración!$H$2:$K$11,3),1) -> #REF! | O30: =IF(OR(#REF!="UP",#REF!="DOWN"),VLOOKUP($C30,Configuración!$H$2:$K$11,4),1) -> #REF! | P30: =IF(SUM(G30:I30)=0, 0, IF(SUM(G30:I30)=1, G30*M30 + H30*N30 + I30*O30, IF(SUM(G30:I30)=2, 1 - PRODUCT( IF(G30=1,1-M30,1), IF(H30=1,1-N30,1), IF(I30=1,1-O30,1) ), IF(SUM(G30:I30)=3, 1 - PRODUCT(1-M30,1-N30,1-O30), 0 ) ) ) ) -> #REF! | Q30: =P30*E30 -> #REF! | R30: =IF(AND(OR(D30="UP",D30="DOWN"), Q30>0.95), D30, 0) -> #REF! | T30: =IF(R30<>0,Configuración!$E$2,0) -> #REF! | U30: =IF(R30<>0,Configuración!$F$2,0) -> #REF! | V30: =IF(R30<>0,Configuración!$G$2,0) -> #REF! | W30: =IF(R30="DOWN",S30+(S30*T30/100),S30-(S30*T30/100)) -> #REF! | X30: =IF(R30="DOWN",S30-(S30*U30/100),S30+(S30*U30/100)) -> #REF! | Z30: =IF(R30="DOWN",IF(Y30 < S30 * (1 - 0.01), Y30 * (1 + 0.005), ""),IF(Y30 > S30 * (1 + 0.01), Y30 * (1 - 0.005), "")) -> #REF! | AB30: =(($B$1) *(T30))/100 -> #REF! | AG30: =IF(R30="DOWN",(S30-AA30)/S30*1000,(AA30-S30)/S30*1000) -> #REF! | AH30: =AB30*(AG30) -> #REF! | AI30: =IF(AK30<V30,"MANTENER","CERRAR") -> #REF!
A31: 45919 | B31: 0.625 | C31: USDCHF | D31: =IF(COUNTIF(#REF!,"<>NAN")=0, 0, IF(AND(OR(#REF!=#REF!,#REF!="NAN"), OR(#REF!=#REF!,#REF!="NAN"), OR(#REF!=#REF!,#REF!="NAN")),#REF!, 0)) -> #REF! | E31: =IF(#REF!="NAN","",IF( AND(OR(#REF!=#REF!,#REF!="NAN"), OR(#REF!=#REF!,#REF!="NAN"), OR(#REF!=#REF!,#REF!="NAN")), 1, 0)) -> #REF! | G31: =IF(OR(#REF!="UP",#REF!="DOWN"),1,0) -> #REF! | H31: =IF(OR(#REF!="UP",#REF!="DOWN"),1,0) -> #REF! | I31: =IF(OR(#REF!="UP",#REF!="DOWN"),1,0) -> #REF! | M31: =IF(OR(#REF!="UP",#REF!="DOWN"),1,1) -> #REF! | N31: =IF(OR(#REF!="UP",#REF!="DOWN"),VLOOKUP($C31,Configuración!$H$2:$K$11,3),1) -> #REF! | O31: =IF(OR(#REF!="UP",#REF!="DOWN"),VLOOKUP($C31,Configuración!$H$2:$K$11,4),1) -> #REF! | P31: =IF(SUM(G31:I31)=0, 0, IF(SUM(G31:I31)=1, G31*M31 + H31*N31 + I31*O31, IF(SUM(G31:I31)=2, 1 - PRODUCT( IF(G31=1,1-M31,1), IF(H31=1,1-N31,1), IF(I31=1,1-O31,1) ), IF(SUM(G31:I31)=3, 1 - PRODUCT(1-M31,1-N31,1-O31), 0 ) ) ) ) -> #REF! | Q31: =P31*E31 -> #REF! | R31: DOWN | S31: 0.78961 | T31: 1 | U31: 2 | V31: 5 | W31: =IF(R31="DOWN",S31+(S31*T31/100),S31-(S31*T31/100)) -> 0.7975061 | X31: =IF(R31="DOWN",S31-(S31*U31/100),S31+(S31*U31/100)) -> 0.7738178 | Y31: 0.79664 | Z31: =IF(R31="DOWN",IF(Y31 < S31 * (1 - 0.01), Y31 * (1 + 0.005), ""),IF(Y31 > S31 * (1 + 0.01), Y31 * (1 - 0.005), "")) | AB31: =(($B$1) *(T31))/100 -> 0.7204 | AG31: =IF(R31="DOWN",(S31-AA31)/S31*1000,(AA31-S31)/S31*1000) -> 1000 | AH31: =AB31*(AG31) -> 720.4 | AI31: =IF(AK31<V31,"MANTENER","CERRAR") -> MANTENER | AK31: 2
A32: 45919 | B32: 0.625 | C32: USDJPY | D32: =IF(COUNTIF(#REF!,"<>NAN")=0, 0, IF(AND(OR(#REF!=#REF!,#REF!="NAN"), OR(#REF!=#REF!,#REF!="NAN"), OR(#REF!=#REF!,#REF!="NAN")),#REF!, 0)) -> #REF! | E32: =IF(#REF!="NAN","",IF( AND(OR(#REF!=#REF!,#REF!="NAN"), OR(#REF!=#REF!,#REF!="NAN"), OR(#REF!=#REF!,#REF!="NAN")), 1, 0)) -> #REF! | G32: =IF(OR(#REF!="UP",#REF!="DOWN"),1,0) -> #REF! | H32: =IF(OR(#REF!="UP",#REF!="DOWN"),1,0) -> #REF! | I32: =IF(OR(#REF!="UP",#REF!="DOWN"),1,0) -> #REF! | M32: =IF(OR(#REF!="UP",#REF!="DOWN"),1,1) -> #REF! | N32: =IF(OR(#REF!="UP",#REF!="DOWN"),VLOOKUP($C32,Configuración!$H$2:$K$11,3),1) -> #REF! | O32: =IF(OR(#REF!="UP",#REF!="DOWN"),VLOOKUP($C32,Configuración!$H$2:$K$11,4),1) -> #REF! | P32: =IF(SUM(G32:I32)=0, 0, IF(SUM(G32:I32)=1, G32*M32 + H32*N32 + I32*O32, IF(SUM(G32:I32)=2, 1 - PRODUCT( IF(G32=1,1-M32,1), IF(H32=1,1-N32,1), IF(I32=1,1-O32,1) ), IF(SUM(G32:I32)=3, 1 - PRODUCT(1-M32,1-N32,1-O32), 0 ) ) ) ) -> #REF! | Q32: =P32*E32 -> #REF! | R32: =IF(AND(OR(D32="UP",D32="DOWN"), Q32>0.95), D32, 0) -> #REF! | T32: =IF(R32<>0,Configuración!$E$2,0) -> #REF! | U32: =IF(R32<>0,Configuración!$F$2,0) -> #REF! | V32: =IF(R32<>0,Configuración!$G$2,0) -> #REF! | W32: =IF(R32="DOWN",S32+(S32*T32/100),S32-(S32*T32/100)) -> #REF! | X32: =IF(R32="DOWN",S32-(S32*U32/100),S32+(S32*U32/100)) -> #REF! | Z32: =IF(R32="DOWN",IF(Y32 < S32 * (1 - 0.01), Y32 * (1 + 0.005), ""),IF(Y32 > S32 * (1 + 0.01), Y32 * (1 - 0.005), "")) -> #REF! | AB32: =(($B$1) *(T32))/100 -> #REF! | AG32: =IF(R32="DOWN",(S32-AA32)/S32*1000,(AA32-S32)/S32*1000) -> #REF! | AH32: =AB32*(AG32) -> #REF! | AI32: =IF(AK32<V32,"MANTENER","CERRAR") -> #REF!
A33: 45922 | B33: 0.625 | C33: AUDCAD | D33: =IF(COUNTIF(#REF!,"<>NAN")=0, 0, IF(AND(OR(#REF!=#REF!,#REF!="NAN"), OR(#REF!=#REF!,#REF!="NAN"), OR(#REF!=#REF!,#REF!="NAN")),#REF!, 0)) -> #REF! | E33: =IF(#REF!="NAN","",IF( AND(OR(#REF!=#REF!,#REF!="NAN"), OR(#REF!=#REF!,#REF!="NAN"), OR(#REF!=#REF!,#REF!="NAN")), 1, 0)) -> #REF! | G33: =IF(OR(#REF!="UP",#REF!="DOWN"),1,0) -> #REF! | H33: =IF(OR(#REF!="UP",#REF!="DOWN"),1,0) -> #REF! | I33: =IF(OR(#REF!="UP",#REF!="DOWN"),1,0) -> #REF! | M33: =IF(OR(#REF!="UP",#REF!="DOWN"),1,1) -> #REF! | N33: =IF(OR(#REF!="UP",#REF!="DOWN"),VLOOKUP($C33,Configuración!$H$2:$K$11,3),1) -> #REF! | O33: =IF(OR(#REF!="UP",#REF!="DOWN"),VLOOKUP($C33,Configuración!$H$2:$K$11,4),1) -> #REF! | P33: =IF(SUM(G33:I33)=0, 0, IF(SUM(G33:I33)=1, G33*M33 + H33*N33 + I33*O33, IF(SUM(G33:I33)=2, 1 - PRODUCT( IF(G33=1,1-M33,1), IF(H33=1,1-N33,1), IF(I33=1,1-O33,1) ), IF(SUM(G33:I33)=3, 1 - PRODUCT(1-M33,1-N33,1-O33), 0 ) ) ) ) -> #REF! | Q33: =P33*E33 -> #REF! | R33: =IF(AND(OR(D33="UP",D33="DOWN"), Q33>0.95), D33, 0) -> #REF! | T33: =IF(R33<>0,Configuración!$E$2,0) -> #REF! | U33: =IF(R33<>0,Configuración!$F$2,0) -> #REF! | V33: =IF(R33<>0,Configuración!$G$2,0) -> #REF! | W33: =IF(R33="DOWN",S33+(S33*T33/100),S33-(S33*T33/100)) -> #REF! | X33: =IF(R33="DOWN",S33-(S33*U33/100),S33+(S33*U33/100)) -> #REF! | Z33: =IF(R33="DOWN",IF(Y33 < S33 * (1 - 0.01), Y33 * (1 + 0.005), ""),IF(Y33 > S33 * (1 + 0.01), Y33 * (1 - 0.005), "")) -> #REF! | AB33: =(($B$1) *(T33))/100 -> #REF! | AG33: =IF(R33="DOWN",(S33-AA33)/S33*1000,(AA33-S33)/S33*1000) -> #REF! | AH33: =AB33*(AG33) -> #REF! | AI33: =IF(AK33<V33,"MANTENER","CERRAR") -> #REF!
A34: 45922 | B34: 0.625 | C34: AUDUSD | D34: =IF(COUNTIF(#REF!,"<>NAN")=0, 0, IF(AND(OR(#REF!=#REF!,#REF!="NAN"), OR(#REF!=#REF!,#REF!="NAN"), OR(#REF!=#REF!,#REF!="NAN")),#REF!, 0)) -> #REF! | E34: =IF(#REF!="NAN","",IF( AND(OR(#REF!=#REF!,#REF!="NAN"), OR(#REF!=#REF!,#REF!="NAN"), OR(#REF!=#REF!,#REF!="NAN")), 1, 0)) -> #REF! | G34: =IF(OR(#REF!="UP",#REF!="DOWN"),1,0) -> #REF! | H34: =IF(OR(#REF!="UP",#REF!="DOWN"),1,0) -> #REF! | I34: =IF(OR(#REF!="UP",#REF!="DOWN"),1,0) -> #REF! | M34: =IF(OR(#REF!="UP",#REF!="DOWN"),1,1) -> #REF! | N34: =IF(OR(#REF!="UP",#REF!="DOWN"),VLOOKUP($C34,Configuración!$H$2:$K$11,3),1) -> #REF! | O34: =IF(OR(#REF!="UP",#REF!="DOWN"),VLOOKUP($C34,Configuración!$H$2:$K$11,4),1) -> #REF! | P34: =IF(SUM(G34:I34)=0, 0, IF(SUM(G34:I34)=1, G34*M34 + H34*N34 + I34*O34, IF(SUM(G34:I34)=2, 1 - PRODUCT( IF(G34=1,1-M34,1), IF(H34=1,1-N34,1), IF(I34=1,1-O34,1) ), IF(SUM(G34:I34)=3, 1 - PRODUCT(1-M34,1-N34,1-O34), 0 ) ) ) ) -> #REF! | Q34: =P34*E34 -> #REF! | R34: =IF(AND(OR(D34="UP",D34="DOWN"), Q34>0.95), D34, 0) -> #REF! | T34: =IF(R34<>0,Configuración!$E$2,0) -> #REF! | U34: =IF(R34<>0,Configuración!$F$2,0) -> #REF! | V34: =IF(R34<>0,Configuración!$G$2,0) -> #REF! | W34: =IF(R34="DOWN",S34+(S34*T34/100),S34-(S34*T34/100)) -> #REF! | X34: =IF(R34="DOWN",S34-(S34*U34/100),S34+(S34*U34/100)) -> #REF! | Z34: =IF(R34="DOWN",IF(Y34 < S34 * (1 - 0.01), Y34 * (1 + 0.005), ""),IF(Y34 > S34 * (1 + 0.01), Y34 * (1 - 0.005), "")) -> #REF! | AB34: =(($B$1) *(T34))/100 -> #REF! | AG34: =IF(R34="DOWN",(S34-AA34)/S34*1000,(AA34-S34)/S34*1000) -> #REF! | AH34: =AB34*(AG34) -> #REF! | AI34: =IF(AK34<V34,"MANTENER","CERRAR") -> #REF!
A35: 45922 | B35: 0.625 | C35: CADCHF | D35: =IF(COUNTIF(#REF!,"<>NAN")=0, 0, IF(AND(OR(#REF!=#REF!,#REF!="NAN"), OR(#REF!=#REF!,#REF!="NAN"), OR(#REF!=#REF!,#REF!="NAN")),#REF!, 0)) -> #REF! | E35: =IF(#REF!="NAN","",IF( AND(OR(#REF!=#REF!,#REF!="NAN"), OR(#REF!=#REF!,#REF!="NAN"), OR(#REF!=#REF!,#REF!="NAN")), 1, 0)) -> #REF! | G35: =IF(OR(#REF!="UP",#REF!="DOWN"),1,0) -> #REF! | H35: =IF(OR(#REF!="UP",#REF!="DOWN"),1,0) -> #REF! | I35: =IF(OR(#REF!="UP",#REF!="DOWN"),1,0) -> #REF! | M35: =IF(OR(#REF!="UP",#REF!="DOWN"),1,1) -> #REF! | N35: =IF(OR(#REF!="UP",#REF!="DOWN"),VLOOKUP($C35,Configuración!$H$2:$K$11,3),1) -> #REF! | O35: =IF(OR(#REF!="UP",#REF!="DOWN"),VLOOKUP($C35,Configuración!$H$2:$K$11,4),1) -> #REF! | P35: =IF(SUM(G35:I35)=0, 0, IF(SUM(G35:I35)=1, G35*M35 + H35*N35 + I35*O35, IF(SUM(G35:I35)=2, 1 - PRODUCT( IF(G35=1,1-M35,1), IF(H35=1,1-N35,1), IF(I35=1,1-O35,1) ), IF(SUM(G35:I35)=3, 1 - PRODUCT(1-M35,1-N35,1-O35), 0 ) ) ) ) -> #REF! | Q35: =P35*E35 -> #REF! | R35: =IF(AND(OR(D35="UP",D35="DOWN"), Q35>0.95), D35, 0) -> #REF! | T35: =IF(R35<>0,Configuración!$E$2,0) -> #REF! | U35: =IF(R35<>0,Configuración!$F$2,0) -> #REF! | V35: =IF(R35<>0,Configuración!$G$2,0) -> #REF! | W35: =IF(R35="DOWN",S35+(S35*T35/100),S35-(S35*T35/100)) -> #REF! | X35: =IF(R35="DOWN",S35-(S35*U35/100),S35+(S35*U35/100)) -> #REF! | Z35: =IF(R35="DOWN",IF(Y35 < S35 * (1 - 0.01), Y35 * (1 + 0.005), ""),IF(Y35 > S35 * (1 + 0.01), Y35 * (1 - 0.005), "")) -> #REF! | AB35: =(($B$1) *(T35))/100 -> #REF! | AG35: =IF(R35="DOWN",(S35-AA35)/S35*1000,(AA35-S35)/S35*1000) -> #REF! | AH35: =AB35*(AG35) -> #REF! | AI35: =IF(AK35<V35,"MANTENER","CERRAR") -> #REF!
A36: 45922 | B36: 0.625 | C36: CHFJPY | D36: =IF(COUNTIF(#REF!,"<>NAN")=0, 0, IF(AND(OR(#REF!=#REF!,#REF!="NAN"), OR(#REF!=#REF!,#REF!="NAN"), OR(#REF!=#REF!,#REF!="NAN")),#REF!, 0)) -> #REF! | E36: =IF(#REF!="NAN","",IF( AND(OR(#REF!=#REF!,#REF!="NAN"), OR(#REF!=#REF!,#REF!="NAN"), OR(#REF!=#REF!,#REF!="NAN")), 1, 0)) -> #REF! | G36: =IF(OR(#REF!="UP",#REF!="DOWN"),1,0) -> #REF! | H36: =IF(OR(#REF!="UP",#REF!="DOWN"),1,0) -> #REF! | I36: =IF(OR(#REF!="UP",#REF!="DOWN"),1,0) -> #REF! | M36: =IF(OR(#REF!="UP",#REF!="DOWN"),1,1) -> #REF! | N36: =IF(OR(#REF!="UP",#REF!="DOWN"),VLOOKUP($C36,Configuración!$H$2:$K$11,3),1) -> #REF! | O36: =IF(OR(#REF!="UP",#REF!="DOWN"),VLOOKUP($C36,Configuración!$H$2:$K$11,4),1) -> #REF! | P36: =IF(SUM(G36:I36)=0, 0, IF(SUM(G36:I36)=1, G36*M36 + H36*N36 + I36*O36, IF(SUM(G36:I36)=2, 1 - PRODUCT( IF(G36=1,1-M36,1), IF(H36=1,1-N36,1), IF(I36=1,1-O36,1) ), IF(SUM(G36:I36)=3, 1 - PRODUCT(1-M36,1-N36,1-O36), 0 ) ) ) ) -> #REF! | Q36: =P36*E36 -> #REF! | R36: =IF(AND(OR(D36="UP",D36="DOWN"), Q36>0.95), D36, 0) -> #REF! | T36: =IF(R36<>0,Configuración!$E$2,0) -> #REF! | U36: =IF(R36<>0,Configuración!$F$2,0) -> #REF! | V36: =IF(R36<>0,Configuración!$G$2,0) -> #REF! | W36: =IF(R36="DOWN",S36+(S36*T36/100),S36-(S36*T36/100)) -> #REF! | X36: =IF(R36="DOWN",S36-(S36*U36/100),S36+(S36*U36/100)) -> #REF! | Z36: =IF(R36="DOWN",IF(Y36 < S36 * (1 - 0.01), Y36 * (1 + 0.005), ""),IF(Y36 > S36 * (1 + 0.01), Y36 * (1 - 0.005), "")) -> #REF! | AB36: =(($B$1) *(T36))/100 -> #REF! | AG36: =IF(R36="DOWN",(S36-AA36)/S36*1000,(AA36-S36)/S36*1000) -> #REF! | AH36: =AB36*(AG36) -> #REF! | AI36: =IF(AK36<V36,"MANTENER","CERRAR") -> #REF!
A37: 45922 | B37: 0.625 | C37: EURAUD | D37: =IF(COUNTIF(#REF!,"<>NAN")=0, 0, IF(AND(OR(#REF!=#REF!,#REF!="NAN"), OR(#REF!=#REF!,#REF!="NAN"), OR(#REF!=#REF!,#REF!="NAN")),#REF!, 0)) -> #REF! | E37: =IF(#REF!="NAN","",IF( AND(OR(#REF!=#REF!,#REF!="NAN"), OR(#REF!=#REF!,#REF!="NAN"), OR(#REF!=#REF!,#REF!="NAN")), 1, 0)) -> #REF! | G37: =IF(OR(#REF!="UP",#REF!="DOWN"),1,0) -> #REF! | H37: =IF(OR(#REF!="UP",#REF!="DOWN"),1,0) -> #REF! | I37: =IF(OR(#REF!="UP",#REF!="DOWN"),1,0) -> #REF! | M37: =IF(OR(#REF!="UP",#REF!="DOWN"),1,1) -> #REF! | N37: =IF(OR(#REF!="UP",#REF!="DOWN"),VLOOKUP($C37,Configuración!$H$2:$K$11,3),1) -> #REF! | O37: =IF(OR(#REF!="UP",#REF!="DOWN"),VLOOKUP($C37,Configuración!$H$2:$K$11,4),1) -> #REF! | P37: =IF(SUM(G37:I37)=0, 0, IF(SUM(G37:I37)=1, G37*M37 + H37*N37 + I37*O37, IF(SUM(G37:I37)=2, 1 - PRODUCT( IF(G37=1,1-M37,1), IF(H37=1,1-N37,1), IF(I37=1,1-O37,1) ), IF(SUM(G37:I37)=3, 1 - PRODUCT(1-M37,1-N37,1-O37), 0 ) ) ) ) -> #REF! | Q37: =P37*E37 -> #REF! | R37: =IF(AND(OR(D37="UP",D37="DOWN"), Q37>0.95), D37, 0) -> #REF! | T37: =IF(R37<>0,Configuración!$E$2,0) -> #REF! | U37: =IF(R37<>0,Configuración!$F$2,0) -> #REF! | V37: =IF(R37<>0,Configuración!$G$2,0) -> #REF! | W37: =IF(R37="DOWN",S37+(S37*T37/100),S37-(S37*T37/100)) -> #REF! | X37: =IF(R37="DOWN",S37-(S37*U37/100),S37+(S37*U37/100)) -> #REF! | Z37: =IF(R37="DOWN",IF(Y37 < S37 * (1 - 0.01), Y37 * (1 + 0.005), ""),IF(Y37 > S37 * (1 + 0.01), Y37 * (1 - 0.005), "")) -> #REF! | AB37: =(($B$1) *(T37))/100 -> #REF! | AG37: =IF(R37="DOWN",(S37-AA37)/S37*1000,(AA37-S37)/S37*1000) -> #REF! | AH37: =AB37*(AG37) -> #REF! | AI37: =IF(AK37<V37,"MANTENER","CERRAR") -> #REF!
